Workbook

Sheet METRICAS
A1: ALAN GALIANO DISTRIBUCIONES — PANEL DE CONTROL 2026
A2: Gas envasado a domicilio · 365 días al año · Santa Fe · 3425-331010
A4: RESUMEN DEL AÑO
A5: =B22 | D5: =C22 | G5: =IFERROR(C22/B22,0) | J5: =E22 | M5: 698 | P5: 492 | S5: $46,102
A6: FACTURADO AÑO | D6: GANANCIA AÑO | G6: % GANANCIA | J6: Nº VENTAS | M6: CLIENTES | P6: A REACTIVAR | S6: PROM. VENTA
A8: RESUMEN MENSUAL
A9: MES | B9: FACTURADO ($) | C9: GANANCIA ($) | D9: % GANANCIA | E9: Nº VENTAS | F9: 10 | G9: 15 | H9: 45 | I9: EFECTIVO ($) | J9: TRANSFER ($) | K9: PROM. VENTA ($) | M9: Mes | N9: Facturado | O9: Ganancia
A10: Enero | B10: =IFERROR(Enero!O11,0) | C10: =IFERROR(Enero!O12,0) | D10: =IFERROR(C10/B10,0) | E10: =IFERROR(Enero!O18,0) | F10: =IFERROR(Enero!O5,0) | G10: =IFERROR(Enero!O6,0) | H10: =IFERROR(Enero!O7,0) | I10: =IFERROR(Enero!O15,0) | J10: =IFERROR(Enero!O16,0) | K10: =IFERROR(B10/E10,0) | M10: Enero | N10: =IFERROR(Enero!O11,0) | O10: =IFERROR(Enero!O12,0)
A11: Febrero | B11: =IFERROR(Febrero!O11,0) | C11: =IFERROR(Febrero!O12,0) | D11: =IFERROR(C11/B11,0) | E11: =IFERROR(Febrero!O18,0) | F11: =IFERROR(Febrero!O5,0) | G11: =IFERROR(Febrero!O6,0) | H11: =IFERROR(Febrero!O7,0) | I11: =IFERROR(Febrero!O15,0) | J11: =IFERROR(Febrero!O16,0) | K11: =IFERROR(B11/E11,0) | M11: Febrero | N11: =IFERROR(Febrero!O11,0) | O11: =IFERROR(Febrero!O12,0)
A12: Marzo | B12: =IFERROR(Marzo!O11,0) | C12: =IFERROR(Marzo!O12,0) | D12: =IFERROR(C12/B12,0) | E12: =IFERROR(Marzo!O18,0) | F12: =IFERROR(Marzo!O5,0) | G12: =IFERROR(Marzo!O6,0) | H12: =IFERROR(Marzo!O7,0) | I12: =IFERROR(Marzo!O15,0) | J12: =IFERROR(Marzo!O16,0) | K12: =IFERROR(B12/E12,0) | M12: Marzo | N12: =IFERROR(Marzo!O11,0) | O12: =IFERROR(Marzo!O12,0)
A13: Abril | B13: =IFERROR(Abril!O11,0) | C13: =IFERROR(Abril!O12,0) | D13: =IFERROR(C13/B13,0) | E13: =IFERROR(Abril!O18,0) | F13: =IFERROR(Abril!O5,0) | G13: =IFERROR(Abril!O6,0) | H13: =IFERROR(Abril!O7,0) | I13: =IFERROR(Abril!O15,0) | J13: =IFERROR(Abril!O16,0) | K13: =IFERROR(B13/E13,0) | M13: Abril | N13: =IFERROR(Abril!O11,0) | O13: =IFERROR(Abril!O12,0)
A14: Mayo | B14: =IFERROR(Mayo!O11,0) | C14: =IFERROR(Mayo!O12,0) | D14: =IFERROR(C14/B14,0) | E14: =IFERROR(Mayo!O18,0) | F14: =IFERROR(Mayo!O5,0) | G14: =IFERROR(Mayo!O6,0) | H14: =IFERROR(Mayo!O7,0) | I14: =IFERROR(Mayo!O15,0) | J14: =IFERROR(Mayo!O16,0) | K14: =IFERROR(B14/E14,0) | M14: Mayo | N14: =IFERROR(Mayo!O11,0) | O14: =IFERROR(Mayo!O12,0)
A15: Junio | B15: =IFERROR(Junio!O11,0) | C15: =IFERROR(Junio!O12,0) | D15: =IFERROR(C15/B15,0) | E15: =IFERROR(Junio!O18,0) | F15: =IFERROR(Junio!O5,0) | G15: =IFERROR(Junio!O6,0) | H15: =IFERROR(Junio!O7,0) | I15: =IFERROR(Junio!O15,0) | J15: =IFERROR(Junio!O16,0) | K15: =IFERROR(B15/E15,0) | M15: Junio | N15: =IFERROR(Junio!O11,0) | O15: =IFERROR(Junio!O12,0)
A16: Julio | B16: =IFERROR(Julio!O11,0) | C16: =IFERROR(Julio!O12,0) | D16: =IFERROR(C16/B16,0) | E16: =IFERROR(Julio!O18,0) | F16: =IFERROR(Julio!O5,0) | G16: =IFERROR(Julio!O6,0) | H16: =IFERROR(Julio!O7,0) | I16: =IFERROR(Julio!O15,0) | J16: =IFERROR(Julio!O16,0) | K16: =IFERROR(B16/E16,0) | M16: Julio | N16: =IFERROR(Julio!O11,0) | O16: =IFERROR(Julio!O12,0)
A17: Agosto | B17: =IFERROR(Agosto!O11,0) | C17: =IFERROR(Agosto!O12,0) | D17: =IFERROR(C17/B17,0) | E17: =IFERROR(Agosto!O18,0) | F17: =IFERROR(Agosto!O5,0) | G17: =IFERROR(Agosto!O6,0) | H17: =IFERROR(Agosto!O7,0) | I17: =IFERROR(Agosto!O15,0) | J17: =IFERROR(Agosto!O16,0) | K17: =IFERROR(B17/E17,0) | M17: Agosto | N17: =IFERROR(Agosto!O11,0) | O17: =IFERROR(Agosto!O12,0)
A18: Septiembre | B18: =IFERROR(Septiembre!O11,0) | C18: =IFERROR(Septiembre!O12,0) | D18: =IFERROR(C18/B18,0) | E18: =IFERROR(Septiembre!O18,0) | F18: =IFERROR(Septiembre!O5,0) | G18: =IFERROR(Septiembre!O6,0) | H18: =IFERROR(Septiembre!O7,0) | I18: =IFERROR(Septiembre!O15,0) | J18: =IFERROR(Septiembre!O16,0) | K18: =IFERROR(B18/E18,0) | M18: Septiembre | N18: =IFERROR(Septiembre!O11,0) | O18: =IFERROR(Septiembre!O12,0)
A19: Octubre | B19: =IFERROR(Octubre!O11,0) | C19: =IFERROR(Octubre!O12,0) | D19: =IFERROR(C19/B19,0) | E19: =IFERROR(Octubre!O18,0) | F19: =IFERROR(Octubre!O5,0) | G19: =IFERROR(Octubre!O6,0) | H19: =IFERROR(Octubre!O7,0) | I19: =IFERROR(Octubre!O15,0) | J19: =IFERROR(Octubre!O16,0) | K19: =IFERROR(B19/E19,0) | M19: Octubre | N19: =IFERROR(Octubre!O11,0) | O19: =IFERROR(Octubre!O12,0)
A20: Noviembre | B20: =IFERROR(Noviembre!O11,0) | C20: =IFERROR(Noviembre!O12,0) | D20: =IFERROR(C20/B20,0) | E20: =IFERROR(Noviembre!O18,0) | F20: =IFERROR(Noviembre!O5,0) | G20: =IFERROR(Noviembre!O6,0) | H20: =IFERROR(Noviembre!O7,0) | I20: =IFERROR(Noviembre!O15,0) | J20: =IFERROR(Noviembre!O16,0) | K20: =IFERROR(B20/E20,0) | M20: Noviembre | N20: =IFERROR(Noviembre!O11,0) | O20: =IFERROR(Noviembre!O12,0)
A21: Diciembre | B21: =IFERROR(Diciembre!O11,0) | C21: =IFERROR(Diciembre!O12,0) | D21: =IFERROR(C21/B21,0) | E21: =IFERROR(Diciembre!O18,0) | F21: =IFERROR(Diciembre!O5,0) | G21: =IFERROR(Diciembre!O6,0) | H21: =IFERROR(Diciembre!O7,0) | I21: =IFERROR(Diciembre!O15,0) | J21: =IFERROR(Diciembre!O16,0) | K21: =IFERROR(B21/E21,0) | M21: Diciembre | N21: =IFERROR(Diciembre!O11,0) | O21: =IFERROR(Diciembre!O12,0)
A22: TOTAL AÑO | B22: =SUM(B10:B21) | C22: =SUM(C10:C21) | D22: =IFERROR(C22/B22,0) | E22: =SUM(E10:E21) | F22: =SUM(F10:F21) | G22: =SUM(G10:G21) | H22: =SUM(H10:H21) | I22: =SUM(I10:I21) | J22: =SUM(J10:J21) | K22: =IFERROR(B22/E22,0)
A24: FACTURADO VS GANANCIA POR MES ($)

Sheet COSTOS
A1: COSTOS — Actualizá aquí cuando cambien los precios
A2: ⚠ Cada vez que cambie un costo, agregá una fila nueva con la Fecha Desde. Las ganancias se calculan con el costo vigente a la fecha de cada venta.
A4: COSTOS VIGENTES ACTUALES
A5: PRODUCTO | B5: DESCRIPCION | C5: COSTO UNITARIO ($)
A6: Garrafa 10 | B6: Garrafa 10kg — Doméstico | C6: 15000
A7: Garrafa 15 | B7: Garrafa 15kg — Doméstico | C7: 22500
A8: Garrafa 45 | B8: Garrafa 45kg — Comercial | C8: 60000
A9: Yerba 500gr | B9: Yerba 500 gramos | C9: 2300
A10: Bidón | B10: Bidón de agua | C10: 850
A13: HISTORIAL DE COSTOS CON VIGENCIA — Agregá una fila nueva cada vez que cambien los precios
A14: PRODUCTO | B14: FECHA DESDE | C14: COSTO ($) | D14: NOTAS
A15: Garrafa 10 | B15: 46023 | C15: 10500 | D15: Enero-Febrero
A16: Garrafa 15 | B16: 46023 | C16: 15750 | D16: Enero-Febrero
A17: Garrafa 45 | B17: 46023 | C17: 47000 | D17: Enero-Febrero
A18: Yerba 500gr | B18: 46023 | C18: 2325 | D18: Enero-Febrero
A19: Bidón | B19: 46023 | C19: 800 | D19: Enero-Febrero
A20: Garrafa 10 | B20: 46082 | C20: 13500 | D20: Marzo 1-24
A21: Garrafa 15 | B21: 46082 | C21: 20250 | D21: Marzo 1-24
A22: Garrafa 45 | B22: 46082 | C22: 49000 | D22: Marzo 1-24
A23: Yerba 500gr | B23: 46082 | C23: 2300 | D23: Marzo 1-24
A24: Bidón | B24: 46082 | C24: 850 | D24: Marzo 1-24
A25: Garrafa 10 | B25: 46106 | C25: 15000 | D25: Marzo 25+
A26: Garrafa 15 | B26: 46106 | C26: 22500 | D26: Marzo 25+
... A29: Bidón | B29: 46106 | C29: 850 | D29: Marzo 25+

Sheet Enero
A1: VENTAS — ENERO 2026 | Q1: 🏆 RANKING ENERO
A2: ⚠ El nombre del cliente debe ser EXACTAMENTE igual siempre · La ganancia se calcula con el costo vigente a la fecha | Q2: # | R2: Cliente | S2: Facturado | T2: Ganancia | U2: Pedidos | V2: Últ. compra
Q3: 🥇 | R3: AZCUENAGA 5023 | S3: 551500 | T3: -26000 | U3: 9 | V3: 20/04/2026
A4: FECHA | B4: CLIENTE / DIRECCIÓN | C4: 10 | D4: 15 | E4: 45 | F4: YERBA | G4: AGUA | H4: VALOR ($) | I4: EFECTIVO ($) | J4: TRANSFER ($) | K4: ENVASE ($) | L4: GANANCIA ($) | N4: RESUMEN ENERO | Q4: 🥈 | R4: PANA GENESIO | S4: 520500 | T4: 70500 | U4: 7 | V4: 09/03/2026
A5: 46023 | B5: LOS PORKI | E5: 1 | H5: 69000 | J5: 69000 | L5: =IF(K5<>"",22000+K5,22000) | N5: TOTAL 10 | O5: =IFERROR(SUM(C5:C700),0) | Q5: 🥉 | R5: FILOMENA | S5: 468000 | T5: 78000 | U5: 16 | V5: 20/04/2026
B6: PANA GENESIO | C6: 1 | E6: 1 | H6: 88500 | J6: 88500 | L6: =IF(K6<>"",31000+K6,31000) | N6: TOTAL 15 | O6: =IFERROR(SUM(D5:D700),0) | Q6: 4 | R6: OTNIEL | S6: 423400 | T6: 105700 | U6: 10 | V6: 16/04/2026
B7: TACUARI 5717 | C7: 1 | H7: 19500 | J7: 19500 | L7: =IF(K7<>"",9000+K7,9000) | N7: TOTAL 45 | O7: =IFERROR(SUM(E5:E700),0) | Q7: 5 | R7: CAREN | S7: 414000 | T7: 54000 | U7: 6 | V7: 20/04/2026
A8: 46024 | B8: PANA VIEYTES | E8: 1 | H8: 65000 | I8: 65000 | L8: =IF(K8<>"",18000+K8,18000) | N8: TOTAL YERBA | O8: =IFERROR(SUM(F5:F700),0) | Q8: 6 | R8: EXE | S8: 414000 | T8: 54000 | U8: 6 | V8: 19/04/2026
B9: CAREN | E9: 1 | H9: 69000 | J9: 69000 | L9: =IF(K9<>"",22000+K9,22000) | N9: TOTAL AGUA | O9: =IFERROR(SUM(G5:G700),0) | Q9: 7 | R9: SABOREAR | S9: 329000 | T9: 51500 | U9: 8 | V9: 22/04/2026
B10: EXE | E10: 1 | H10: 69000 | J10: 69000 | L10: =IF(K10<>"",22000+K10,22000) | Q10: 8 | R10: LUCHO | S10: 316300 | T10: -7900 | U10: 13 | V10: 20/04/2026
B11: GARMENDIA 9250 | G11: 2 | H11: 9600 | J11: 9600 | L11: =IF(K11<>"",8000+K11,8000) | N11: FACTURACIÓN | O11: =IFERROR(SUM(H5:H700),0) | Q11: 9 | R11: GOLD BURGUER | S11: 316000 | T11: 76000 | U11: 2 | V11: 20/02/2026
B12: DUSSO 6638 | E12: 1 | H12: 65000 | I12: 65000 | L12: =IF(K12<>"",18000+K12,18000) | N12: GANANCIA | O12: =IFERROR(SUM(L5:L700),0) | Q12: 10 | R12: PANA ALBERTI | S12: 298000 | T12: 43000 | U12: 4 | V12: 22/04/2026
A13: 46025 | B13: FACU DONA | C13: 1 | H13: 13500 | I13: 13500 | L13: =IF(K13<>"",3000+K13,3000) | N13: % GANANCIA | O13: =IFERROR(SUM(L5:L700)/SUM(H5:H700),0) | Q13: 11 | R13: BRASERIA | S13: 282000 | T13: 42000 | U13: 4 | V13: 18/04/2026
B14: VICTO CAPE DRUGSTORE | C14: 1 | H14: 19500 | J14: 19500 | L14: =IF(K14<>"",9000+K14,9000) | Q14: 12 | R14: RIO NEGRO 6558 | S14: 270000 | T14: 210000 | U14: 1 | V14: 13/02/2026
B15: LUCHO | C15: 1 | H15: 13000 | I15: 13000 | L15: =IF(K15<>"",2500+K15,2500) | N15: EFECTIVO | O15: =IFERROR(SUM(I5:I700),0) | Q15: 13 | R15: GOLD COSTA ESTE | S15: 231000 | T15: 51000 | U15: 1 | V15: 06/01/2026
B16: BONEO 5315 | C16: 2 | H16: 41000 | J16: 41000 | L16: =IF(K16<>"",20000+K16,20000) | N16: TRANSFERENCIA | O16: =IFERROR(SUM(J5:J700),0) | Q16: 14 | R16: PANA VIEYTES 4500 | S16: 214000 | T16: 19000 | U16: 3 | V16: 16/04/2026
B17: OTNIEL | E17: 1 | H17: 69000 | J17: 69000 | L17: =IF(K17<>"",22000+K17,22000) | Q17: 15 | R17: 9 DE JULIO 1144 BAR | S17: 152000 | T17: 32000 | U17: 1 | V17: 20/01/2026
B18: ARISTOBULO 5879 | D18: 1 | H18: 34500 | I18: 34500 | L18: =IF(K18<>"",18750+K18,18750) | N18: Nº VENTAS | O18: =IFERROR(COUNTA(B5:B700),0) | Q18: 16 | R18: SANDRA | S18: 149000 | T18: 3950 | U18: 6 | V18: 16/04/2026
B19: SABOREAR | C19: 1 | H19: 18000 | J19: 18000 | L19: =IF(K19<>"",7500+K19,7500) | N19: DÍAS DEL MES | O19: 31 | Q19: 17 | R19: PAULO | S19: 146500 | T19: -11000 | U19: 4 | V19: 13/04/2026
B20: LUCIANDO LEIVA Y ALBERTI | C20: 1 | H20: 20500 | I20: 20500 | L20: =IF(K20<>"",10000+K20,10000) | Q20: 18 | R20: DOMINGO SILVA 4217 | S20: 146500 | T20: -3500 | U20: 2 | V20: 19/04/2026
B21: OTNIEL | G21: 2 | H21: 9600 | I21: 4800 | J21: 4800 | L21: =IF(K21<>"",8000+K21,8000) | N21: OBJETIVO ($) | Q21: 19 | R21: PANA GORRITI | S21: 144000 | T21: 24000 | U21: 2 | V21: 12/01/2026
B22: DIOGENES ANTILLES 675 | E22: 1 | H22: 76000 | J22: 76000 | L22: =IF(K22<>"",29000+K22,29000) | N22: DIFERENCIA | O22: =IFERROR(SUM(L5:L700)-N21,0) | Q22: 20 | R22: ALISOS 5837 | S22: 139500 | T22: 124500 | U22: 1 | V22: 04/01/2026
B23: GRAL PAZ 7826 | C23: 1 | H23: 22000 | I23: 22000 | L23: =IF(K23<>"",11500+K23,11500) | Q23: 21 | R23: PANA VIEYTES | S23: 135700 | T23: 13400 | U23: 5 | V23: 16/01/2026
B24: FILOMENA | C24: 2 | H24: 36000 | J24: 36000 | L24: =IF(K24<>"",15000+K24,15000) | N24: KG BUTANO | O24: =IFERROR((SUM(C5:C700)*10)+(SUM(D5:D700)*15),0) | Q24: 22 | R24: ROTI AGUADO | S24: 115000 | T24: 17500 | U24: 1 | V24: 17/04/2026
B25: SABOREARTE CARRO | C25: 1 | H25: 18000 | J25: 18000 | L25: =IF(K25<>"",7500+K25,7500) | N25: KG PROPANO | O25: =IFERROR(SUM(E5:E700)*45,0) | Q25: 23 | R25: NACHO CUEVA | S25: 115000 | T25: 17500 | U25: 3 | V25: 28/01/2026
B26: DRAXXO | C26: 1 | H26: 22000 | I26: 22000 | L26: =IF(K26<>"",11500+K26,11500) | N26: KG TOTAL | O26: =IFERROR(O24+O25,0) | Q26: 24 | R26: ROTI SAN LORENZO | S26: 107000 | T26: 24500 | U26: 3 | V26: 15/04/2026
B27: TACUARI 5717 | C27: 1 | H27: 19500 | J27: 19500 | L27: =IF(K27<>"",9000+K27,9000) | Q27: 25 | R27: CHICLANA 9671 | S27: 84000 | T27: 24000 | U27: 1 | V27: 03/01/2026
B28: NACHO CUEVA | C28: 2 | H28: 34000 | I28: 34000 | L28: =IF(K28<>"",13000+K28,13000) | N28: TICKET PROM. VENTA | O28: =IFERROR(SUM(H5:H700)/COUNTA(B5:B700),0) | Q28: 26 | R28: D SILVA 4217 | S28: 80500 | T28: -2000 | U28: 1 | V28: 11/04/2026
B29: CHICLANA 9671 | E29: 1 | H29: 84000 | J29: 84000 | L29: =IF(K29<>"",37000+K29,37000) | N29: TICKET PROM. GANANCIA | O29: =IFERROR(SUM(L5:L700)/COUNTA(B5:B700),0) | Q29: 27 | R29: ROTI VIEYTES | S29: 78000 | T29: -12000 | U29: 1 | V29: 17/04/2026
B30: BRASERIA | E30: 1 | H30: 69000 | J30: 69000 | L30: =IF(K30<>"",22000+K30,22000) | Q30: 28 | R30: TACUARI 5717 | S30: 78000 | T30: 18000 | U30: 3 | V30: 11/04/2026
A31: 46026 | B31: PARRILA BLAS PARERA | C31: 1 | H31: 16000 | J31: 16000 | L31: =IF(K31<>"",5500+K31,5500) | Q31: 29 | R31: BENTEVEOS DAMIAN | S31: 78000 | T31: 18000 | U31: 1 | V31: 11/01/2026
B32: ALISOS 5837 | C32: 1 | H32: 139500 | J32: 139500 | L32: =IF(K32<>"",129000+K32,129000) | Q32: 30 | R32: BONEO 5363 | S32: 78000 | T32: 18000 | U32: 1 | V32: 16/01/2026
B33: PANA ALBERTI | C33: 1 | E33: 1 | H33: 87000 | I33: 87000 | L33: =IF(K33<>"",29500+K33,29500) | Q33: 31 | R33: 9 DE JULIO 1144 | S33: 77000 | T33: 17000 | U33: 1 | V33: 06/03/2026
B34: C FUNES 4553 | E34: 1 | H34: 69000 | J34: 69000 | L34: =IF(K34<>"",22000+K34,22000) | Q34: 32 | R34: SAVEDRA 10125 | S34: 77000 | T34: 17000 | U34: 1 | V34: 09/04/2026
B35: J CIBILS 2519 | E35: 1 | H35: 72000 | J35: 72000 | L35: =IF(K35<>"",25000+K35,25000) | Q35: 33 | R35: GASTON AMARAL | S35: 77000 | T35: 17000 | U35: 1 | V35: 15/04/2026
B36: M ZAPATA 3304 | C36: 1 | H36: 22000 | J36: 22000 | L36: =IF(K36<>"",11500+K36,11500) | Q36: 34 | R36: NOGALES 2412 | S36: 77000 | T36: 17000 | U36: 1 | V36: 23/03/2026
B37: SABOREAR | D37: 1 | H37: 27000 | J37: 27000 | L37: =IF(K37<>"",11250+K37,11250) | Q37: 35 | R37: JOSE MONTEVERA | S37: 77000 | T37: 17000 | U37: 1 | V37: 18/03/2026
A38: 46027 | B38: PANA VIEYTES | C38: 1 | H38: 16000 | J38: 16000 | L38: =IF(K38<>"",5500+K38,5500) | Q38: 36 | R38: BAIGORRIA 9350 | S38: 77000 | T38: 17000 | U38: 1 | V38: 24/02/2026
B39: PAULO | C39: 2 | D39: 1 | H39: 45000 | I39: 45000 | L39: =IF(K39<>"",8250+K39,8250) | Q39: 37 | R39: LALO | S39: 77000 | T39: 17000 | U39: 1 | V39: 27/02/2026
B40: SANDRA | C40: 1 | G40: 1 | H40: 17000 | I40: 17000 | L40: =IF(K40<>"",5700+K40,5700) | Q40: 38 | R40: ESPORA 5335 | S40: 77000 | T40: 17000 | U40: 1 | V40: 07/01/2026
...

Sheet Febrero
A1: VENTAS — FEBRERO 2026 | Q1: 🏆 RANKING FEBRERO
A2: ⚠ El nombre del cliente debe ser EXACTAMENTE igual siempre · La ganancia se calcula con el costo vigente a la fecha | Q2: # | R2: Cliente | S2: Facturado | T2: Ganancia | U2: Pedidos | V2: Últ. compra
Q3: 🥇 | R3: OTNIEL | S3: 586000 | T3: 141650 | U3: 9 | V3: 16/04/2026
A4: FECHA | B4: CLIENTE / DIRECCIÓN | C4: 10 | D4: 15 | E4: 45 | F4: YERBA | G4: AGUA | H4: VALOR ($) | I4: EFECTIVO ($) | J4: TRANSFER ($) | K4: ENVASE ($) | L4: GANANCIA ($) | N4: RESUMEN FEBRERO | Q4: 🥈 | R4: PANA GENESIO | S4: 502000 | T4: 67000 | U4: 8 | V4: 09/03/2026
A5: 46054 | B5: GENERAL PAZ 7989 | C5: 1 | H5: 22000 | I5: 22000 | L5: =IF(K5<>"",11500+K5,11500) | N5: TOTAL 10 | O5: =IFERROR(SUM(C5:C700),0) | Q5: 🥉 | R5: CAREN | S5: 423000 | T5: 63000 | U5: 6 | V5: 20/04/2026
B6: POLLERIA BLAS PARERA | C6: 1 | H6: 17000 | I6: 17000 | L6: =IF(K6<>"",6500+K6,6500) | N6: TOTAL 15 | O6: =IFERROR(SUM(D5:D700),0) | Q6: 4 | R6: FILOMENA | S6: 403000 | T6: 73000 | U6: 15 | V6: 20/04/2026
B7: SAVEDRA 1683 | C7: 1 | H7: 22000 | I7: 22000 | L7: =IF(K7<>"",11500+K7,11500) | N7: TOTAL 45 | O7: =IFERROR(SUM(E5:E700),0) | Q7: 5 | R7: SABOREAR | S7: 388500 | T7: 73500 | U7: 10 | V7: 22/04/2026
B8: OTNIEL | C8: 1 | D8: 1 | E8: 1 | G8: 1 | H8: 123500 | I8: 120000 | J8: 3500 | L8: =IF(K8<>"",49450+K8,49450) | N8: TOTAL YERBA | O8: =IFERROR(SUM(F5:F700),0) | Q8: 6 | R8: LUCHO | S8: 370000 | T8: 7450 | U8: 14 | V8: 20/04/2026
B9: PARRI GABOTO | C9: 1 | H9: 19500 | J9: 19500 | L9: =IF(K9<>"",9000+K9,9000) | N9: TOTAL AGUA | O9: =IFERROR(SUM(G5:G700),0) | Q9: 7 | R9: EXE | S9: 351000 | T9: 51000 | U9: 5 | V9: 19/04/2026
B10: SABORERARTE | C10: 1 | E10: 1 | H10: 88000 | J10: 88000 | L10: =IF(K10<>"",30500+K10,30500) | Q10: 8 | R10: GOLD BURGUER | S10: 328000 | T10: 88000 | U10: 2 | V10: 20/02/2026
A11: 46055 | B11: FABIO PARISI | F11: 20 | H11: 67200 | I11: 67200 | L11: =IF(K11<>"",20700+K11,20700) | N11: FACTURACIÓN | O11: =IFERROR(SUM(H5:H700),0) | Q11: 9 | R11: AZCUENAGA 5023 | S11: 305000 | T11: -10000 | U11: 5 | V11: 20/04/2026
B12: SERBNADO BAY0 7165 | C12: 1 | H12: 20500 | I12: 20500 | L12: =IF(K12<>"",10000+K12,10000) | N12: GANANCIA | O12: =IFERROR(SUM(L5:L700),0) | Q12: 10 | R12: BRASERIA | S12: 289000 | T12: 49000 | U12: 4 | V12: 18/04/2026
B13: MAXI HERMANO | G13: 1 | H13: 5000 | J13: 5000 | L13: =IF(K13<>"",4200+K13,4200) | N13: % GANANCIA | O13: =IFERROR(SUM(L5:L700)/SUM(H5:H700),0) | Q13: 11 | R13: ROTI AGUADO | S13: 264500 | T13: 39500 | U13: 4 | V13: 17/04/2026
B14: PALLARES 8200 | C14: 2 | H14: 42000 | J14: 42000 | L14: =IF(K14<>"",21000+K14,21000) | Q14: 12 | R14: ROTI VIEYTES | S14: 222000 | T14: -3000 | U14: 5 | V14: 17/04/2026
B15: FILOMENA | C15: 2 | H15: 36000 | J15: 36000 | L15: =IF(K15<>"",15000+K15,15000) | N15: EFECTIVO | O15: =IFERROR(SUM(I5:I700),0) | Q15: 13 | R15: PANA VIEYTES 4500 | S15: 200000 | T15: 20000 | U15: 3 | V15: 16/04/2026
B16: LUCHO | C16: 1 | H16: 14500 | I16: 14500 | L16: =IF(K16<>"",4000+K16,4000) | N16: TRANSFERENCIA | O16: =IFERROR(SUM(J5:J700),0) | Q16: 14 | R16: SANDRA | S16: 199000 | T16: 5200 | U16: 8 | V16: 16/04/2026
B17: BRAILE 7173 | C17: 1 | H17: 21000 | I17: 21000 | L17: =IF(K17<>"",10500+K17,10500) | Q17: 15 | R17: PANA ALBERTI | S17: 191500 | T17: 34000 | U17: 4 | V17: 22/04/2026
B18: AZCUENAGA 5023 | C18: 1 | H18: 14500 | J18: 14500 | L18: =IF(K18<>"",4000+K18,4000) | N18: Nº VENTAS | O18: =IFERROR(COUNTA(B5:B700),0) | Q18: 16 | R18: COGORNO 5520 | S18: 190500 | T18: -4500 | U18: 3 | V18: 25/03/2026
A19: 46056 | B19: VICTOR CAPE | C19: 1 | H19: 20500 | J19: 20500 | L19: =IF(K19<>"",10000+K19,10000) | N19: DÍAS DEL MES | O19: 28 | Q19: 17 | R19: NACHO | S19: 174500 | T19: 32000 | U19: 8 | V19: 02/04/2026
B20: PANA VIEYTES GISELA | C20: 1 | H20: 17500 | J20: 17500 | L20: =IF(K20<>"",7000+K20,7000) | Q20: 18 | R20: ROTI SAN LORENZO | S20: 163000 | T20: 35500 | U20: 2 | V20: 15/04/2026
B21: RUPERTO GODOY 1278 | E21: 1 | H21: 72500 | I21: 72500 | L21: =IF(K21<>"",25500+K21,25500) | N21: OBJETIVO ($) | Q21: 19 | R21: 20 DE JUNIO Y 9 DE JULIO | S21: 156000 | T21: 36000 | U21: 1 | V21: 17/02/2026
B22: LUCHO | C22: 1 | H22: 14500 | I22: 14500 | L22: =IF(K22<>"",4000+K22,4000) | N22: DIFERENCIA | O22: =IFERROR(SUM(L5:L700)-N21,0) | Q22: 20 | R22: 9 DE JULIO 1144 | S22: 154000 | T22: 34000 | U22: 1 | V22: 06/03/2026
B23: BEATRIZ | G23: 1 | H23: 5000 | I23: 5000 | L23: =IF(K23<>"",4200+K23,4200) | Q23: 21 | R23: PANA GORRITI 4600 | S23: 148000 | T23: 28000 | U23: 2 | V23: 08/04/2026
B24: EX COMBATIENTES 5220 | C24: 2 | H24: 42000 | J24: 42000 | L24: =IF(K24<>"",21000+K24,21000) | N24: KG BUTANO | O24: =IFERROR((SUM(C5:C700)*10)+(SUM(D5:D700)*15),0) | Q24: 22 | R24: PAULO | S24: 145000 | T24: -5000 | U24: 4 | V24: 13/04/2026
B25: MOLINA FLORES 1 | E25: 1 | H25: 75000 | I25: 75000 | L25: =IF(K25<>"",28000+K25,28000) | N25: KG PROPANO | O25: =IFERROR(SUM(E5:E700)*45,0) | Q25: 23 | R25: PANA VIEYTES 3800 | S25: 143000 | T25: 23000 | U25: 2 | V25: 08/04/2026
B26: PANA VIEYTES 3800 | E26: 1 | H26: 71000 | J26: 71000 | L26: =IF(K26<>"",24000+K26,24000) | N26: KG TOTAL | O26: =IFERROR(O24+O25,0) | Q26: 24 | R26: PANA BERUTI 6400 | S26: 132000 | T26: 12000 | U26: 2 | V26: 22/04/2026
B27: LA SALLE 3151 | E27: 1 | H27: 73500 | I27: 73500 | L27: =IF(K27<>"",26500+K27,26500) | Q27: 25 | R27: MARTINEZ 3221 | S27: 119000 | T27: 29000 | U27: 1 | V27: 25/03/2026
B28: GENERAL PAZ 6050 | C28: 1 | H28: 22000 | J28: 22000 | L28: =IF(K28<>"",11500+K28,11500) | N28: TICKET PROM. VENTA | O28: =IFERROR(SUM(H5:H700)/COUNTA(B5:B700),0) | Q28: 26 | R28: GENERAL PAZ 7826 | S28: 118000 | T28: 28000 | U28: 2 | V28: 13/02/2026
B29: ESMERALDA 2376 | E29: 1 | H29: 75000 | J29: 75000 | L29: =IF(K29<>"",28000+K29,28000) | N29: TICKET PROM. GANANCIA | O29: =IFERROR(SUM(L5:L700)/COUNTA(B5:B700),0) | Q29: 27 | R29: SABORERARTE | S29: 107500 | T29: 17500 | U29: 2 | V29: 26/02/2026
B30: FABIAN BLAS PARERA | C30: 1 | D30: 1 | H30: 50000 | I30: 50000 | L30: =IF(K30<>"",23750+K30,23750) | Q30: 28 | R30: GRINGO ILGATO | S30: 99000 | T30: 24000 | U30: 1 | V30: 08/02/2026
B31: PANA VIEYTES 4500 | E31: 1 | H31: 66000 | I31: 66000 | L31: =IF(K31<>"",19000+K31,19000) | Q31: 29 | R31: MISIONES 6381 PANA | S31: 93000 | T31: 18000 | U31: 1 | V31: 12/02/2026
B32: SANDRA | C32: 2 | H32: 29000 | I32: 29000 | L32: =IF(K32<>"",8000+K32,8000) | Q32: 30 | R32: AZCUEJAGA 5023 | S32: 90000 | T32: 0 | U32: 1 | V32: 27/02/2026
B33: AYACUCHO 5370 | G33: 2 | H33: 10000 | J33: 10000 | L33: =IF(K33<>"",8400+K33,8400) | Q33: 31 | R33: PANA BONEO | S33: 82500 | T33: 7500 | U33: 1 | V33: 16/02/2026
B34: FILOMENA | C34: 1 | H34: 18000 | J34: 18000 | L34: =IF(K34<>"",7500+K34,7500) | Q34: 32 | R34: DOMINGO SIVLA 4217 | S34: 80500 | T34: -2000 | U34: 1 | V34: 09/03/2026
A35: 46057 | B35: COGORNO 5520 | C35: 5 | H35: 72500 | I35: 72500 | L35: =IF(K35<>"",20000+K35,20000) | Q35: 33 | R35: SAN JOSE 8494 | S35: 79000 | T35: 19000 | U35: 1 | V35: 08/02/2026
B36: OTNIEL | G36: 4 | H36: 20000 | I36: 20000 | L36: =IF(K36<>"",16800+K36,16800) | Q36: 34 | R36: ORREGO Y MENDIETA | S36: 79000 | T36: 19000 | U36: 1 | V36: 27/02/2026
B37: LAVADERO | D37: 1 | H37: 22000 | J37: 22000 | L37: =IF(K37<>"",6250+K37,6250) | Q37: 35 | R37: RIO NEGRO 6570 | S37: 79000 | T37: 19000 | U37: 1 | V37: 28/02/2026
B38: ALBERTI 5122 | E38: 1 | H38: 75000 | J38: 75000 | L38: =IF(K38<>"",28000+K38,28000) | Q38: 36 | R38: IL GATO PEPE | S38: 78000 | T38: 18000 | U38: 1 | V38: 17/02/2026
B39: NACHO | D39: 1 | H39: 27000 | J39: 27000 | L39: =IF(K39<>"",11250+K39,11250) | Q39: 37 | R39: RIO NEGRO 6558 | S39: 77000 | T39: 17000 | U39: 1 | V39: 13/02/2026
B40: ALBERTI 5303 | C40: 1 | H40: 21000 | I40: 21000 | L40: =IF(K40<>"",10500+K40,10500) | Q40: 38 | R40: ALSINA 9251 | S40: 77000 | T40: 17000 | U40: 1 | V40: 23/03/2026
...

Sheet Marzo
A1: VENTAS — MARZO 2026 | Q1: 🏆 RANKING MARZO
A2: ⚠ El nombre del cliente debe ser EXACTAMENTE igual siempre · La ganancia se calcula con el costo vigente a la fecha | Q2: # | R2: Cliente | S2: Facturado | T2: Ganancia | U2: Pedidos | V2: Últ. compra
Q3: 🥇 | R3: OTNIEL | S3: 556000 | T3: 157500 | U3: 10 | V3: 16/04/2026
A4: FECHA | B4: CLIENTE / DIRECCIÓN | C4: 10 | D4: 15 | E4: 45 | F4: YERBA | G4: AGUA | H4: VALOR ($) | I4: EFECTIVO ($) | J4: TRANSFER ($) | K4: ENVASE ($) | L4: GANANCIA ($) | N4: RESUMEN MARZO | Q4: 🥈 | R4: AZCUENAGA 5023 | S4: 413000 | T4: 15500 | U4: 5 | V4: 20/04/2026
A5: 46082 | B5: JOSE CIBILS | E5: 1 | H5: 76000 | J5: 76000 | L5: =IF(K5<>"",27000+K5,27000) | N5: TOTAL 10 | O5: =IFERROR(SUM(C5:C700),0) | Q5: 🥉 | R5: FILOMENA | S5: 357000 | T5: 87000 | U5: 11 | V5: 20/04/2026
B6: ALSINA 6550 | D6: 1 | H6: 33000 | I6: 33000 | L6: =IF(K6<>"",12750+K6,12750) | N6: TOTAL 15 | O6: =IFERROR(SUM(D5:D700),0) | Q6: 4 | R6: EXE | S6: 342000 | T6: 72000 | U6: 4 | V6: 19/04/2026
B7: LAS HERAS Y GORRITI | E7: 1 | H7: 75000 | J7: 75000 | L7: =IF(K7<>"",26000+K7,26000) | N7: TOTAL 45 | O7: =IFERROR(SUM(E5:E700),0) | Q7: 5 | R7: CAREN | S7: 298000 | T7: 58000 | U7: 4 | V7: 20/04/2026
B8: RIVADAVIA 6330 | D8: 1 | H8: 33000 | J8: 33000 | L8: =IF(K8<>"",12750+K8,12750) | N8: TOTAL YERBA | O8: =IFERROR(SUM(F5:F700),0) | Q8: 6 | R8: SABOREAR | S8: 274000 | T8: 64000 | U8: 7 | V8: 22/04/2026
B9: BERUTI 4075 | E9: 2 | H9: 152000 | J9: 152000 | L9: =IF(K9<>"",54000+K9,54000) | N9: TOTAL AGUA | O9: =IFERROR(SUM(G5:G700),0) | Q9: 7 | R9: LUCHO | S9: 252500 | T9: 19150 | U9: 11 | V9: 20/04/2026
B10: 9 DE JULIO 2109 | C10: 1 | H10: 23000 | J10: 23000 | L10: =IF(K10<>"",9500+K10,9500) | Q10: 8 | R10: BRASERIA | S10: 229000 | T10: 49000 | U10: 3 | V10: 18/04/2026
B11: NACHO | C11: 1 | H11: 19000 | J11: 19000 | L11: =IF(K11<>"",5500+K11,5500) | N11: FACTURACIÓN | O11: =IFERROR(SUM(H5:H700),0) | Q11: 9 | R11: PANA ALBERTI | S11: 221000 | T11: 41000 | U11: 3 | V11: 22/04/2026
A12: 46083 | B12: IRMA INGENIEROS 5501 | C12: 1 | H12: 23000 | I12: 23000 | L12: =IF(K12<>"",9500+K12,9500) | N12: GANANCIA | O12: =IFERROR(SUM(L5:L700),0) | Q12: 10 | R12: MARIELA | S12: 219000 | T12: 53000 | U12: 1 | V12: 25/03/2026
B13: GENEIRO 8249 | C13: 1 | H13: 21000 | J13: 21000 | L13: =IF(K13<>"",7500+K13,7500) | N13: % GANANCIA | O13: =IFERROR(SUM(L5:L700)/SUM(H5:H700),0) | Q13: 11 | R13: PANA VIEYTES 4500 | S13: 214000 | T13: 34000 | U13: 3 | V13: 16/04/2026
B14: VIANDAS JORGE | C14: 1 | H14: 19000 | I14: 19000 | L14: =IF(K14<>"",5500+K14,5500) | Q14: 12 | R14: SANDRA | S14: 207000 | T14: 25300 | U14: 10 | V14: 16/04/2026
B15: 25 DE MAYO 8347 | C15: 1 | H15: 21000 | I15: 21000 | L15: =IF(K15<>"",7500+K15,7500) | N15: EFECTIVO | O15: =IFERROR(SUM(I5:I700),0) | Q15: 13 | R15: NACHO | S15: 179500 | T15: 22000 | U15: 7 | V15: 02/04/2026
B16: RICARDO ALDAO 3082 | C16: 1 | H16: 22000 | I16: 22000 | L16: =IF(K16<>"",8500+K16,8500) | N16: TRANSFERENCIA | O16: =IFERROR(SUM(J5:J700),0) | Q16: 14 | R16: DUSO 7678 | S16: 178500 | T16: 21000 | U16: 1 | V16: 22/03/2026
B17: B IRIGOYEN 6634 | C17: 1 | H17: 22000 | I17: 22000 | L17: =IF(K17<>"",8500+K17,8500) | Q17: 15 | R17: PANA GENESIO | S17: 176000 | T17: 26000 | U17: 4 | V17: 09/03/2026
B18: CAMELI 4860 | C18: 2 | H18: 42000 | J18: 42000 | L18: =IF(K18<>"",15000+K18,15000) | N18: Nº VENTAS | O18: =IFERROR(COUNTA(B5:B700),0) | Q18: 16 | R18: COGORNO 5520 | S18: 170000 | T18: 20000 | U18: 2 | V18: 25/03/2026
B19: VICTOR CAPE | D19: 1 | H19: 32000 | J19: 32000 | L19: =IF(K19<>"",11750+K19,11750) | N19: DÍAS DEL MES | O19: 31 | Q19: 17 | R19: J D SOLIS 10529 | S19: 166000 | T19: 46000 | U19: 1 | V19: 14/03/2026
B20: FILOMENA | C20: 2 | H20: 38000 | I20: 38000 | L20: =IF(K20<>"",11000+K20,11000) | Q20: 18 | R20: 9 DE JULIO 1144 | S20: 158000 | T20: 38000 | U20: 1 | V20: 06/03/2026
A21: 46084 | B21: OTNIEL | C21: 1 | D21: 1 | E21: 1 | G21: 1 | H21: 127500 | J21: 127500 | L21: =IF(K21<>"",43900+K21,43900) | N21: OBJETIVO ($) | Q21: 19 | R21: GRAL PAZ 7826 | S21: 156000 | T21: 36000 | U21: 1 | V21: 14/03/2026
B22: ALBERTI 5251 | C22: 1 | H22: 21000 | I22: 21000 | L22: =IF(K22<>"",7500+K22,7500) | N22: DIFERENCIA | O22: =IFERROR(SUM(L5:L700)-N21,0) | Q22: 20 | R22: PANA GORRITI 4600 | S22: 153000 | T22: 33000 | U22: 2 | V22: 08/04/2026
B23: LUCHO | C23: 1 | H23: 15000 | I23: 15000 | L23: =IF(K23<>"",1500+K23,1500) | Q23: 21 | R23: BERUTI 4075 | S23: 152000 | T23: 32000 | U23: 1 | V23: 01/03/2026
B24: PIEDRABUENA 4506 | E24: 1 | H24: 77000 | I24: 77000 | L24: =IF(K24<>"",28000+K24,28000) | N24: KG BUTANO | O24: =IFERROR((SUM(C5:C700)*10)+(SUM(D5:D700)*15),0) | Q24: 22 | R24: PANA VIEYTE 3800 | S24: 148000 | T24: 28000 | U24: 1 | V24: 05/03/2026
B25: EX COMBATIENTES 6532 | D25: 1 | H25: 32000 | I25: 32000 | L25: =IF(K25<>"",11750+K25,11750) | N25: KG PROPANO | O25: =IFERROR(SUM(E5:E700)*45,0) | Q25: 23 | R25: D SILVA 4217 | S25: 145500 | T25: 10500 | U25: 3 | V25: 11/04/2026
B26: AZOPARD0 10560 | C26: 1 | H26: 21000 | I26: 21000 | L26: =IF(K26<>"",7500+K26,7500) | N26: KG TOTAL | O26: =IFERROR(O24+O25,0) | Q26: 24 | R26: ROTI AGUADO | S26: 135000 | T26: 30000 | U26: 2 | V26: 17/04/2026
B27: PANA GENESIO | E27: 1 | H27: 69000 | J27: 69000 | L27: =IF(K27<>"",20000+K27,20000) | Q27: 25 | R27: MARCE DUSSO | S27: 132000 | T27: 12000 | U27: 1 | V27: 10/03/2026
B28: POLLERIA BLASPA | C28: 1 | H28: 18000 | I28: 18000 | L28: =IF(K28<>"",4500+K28,4500) | N28: TICKET PROM. VENTA | O28: =IFERROR(SUM(H5:H700)/COUNTA(B5:B700),0) | Q28: 26 | R28: MARTINEZ 3221 | S28: 108000 | T28: 33000 | U28: 1 | V28: 25/03/2026
B29: SANDRA | C29: 1 | H29: 15500 | I29: 15500 | L29: =IF(K29<>"",2000+K29,2000) | N29: TICKET PROM. GANANCIA | O29: =IFERROR(SUM(L5:L700)/COUNTA(B5:B700),0) | Q29: 27 | R29: GABOTO 7320 | S29: 105000 | T29: 30000 | U29: 1 | V29: 26/03/2026
B30: F5 GABOTO | C30: 1 | H30: 20000 | I30: 20000 | L30: =IF(K30<>"",6500+K30,6500) | Q30: 28 | R30: PUBLICO 2383 | S30: 104000 | T30: 29000 | U30: 1 | V30: 11/03/2026
B31: SARSOTI 6567 | D31: 1 | H31: 30000 | J31: 30000 | L31: =IF(K31<>"",9750+K31,9750) | Q31: 29 | R31: ALSINA 9251 | S31: 103000 | T31: 28000 | U31: 1 | V31: 23/03/2026
B32: ALBERTI 4930 | E32: 1 | G32: 1 | H32: 86000 | J32: 86000 | L32: =IF(K32<>"",36150+K32,36150) | Q32: 30 | R32: DOMINGO SILVA 4217 | S32: 102000 | T32: 12000 | U32: 2 | V32: 19/04/2026
B33: ROQUE S PENA 7668 | E33: 1 | H33: 73000 | J33: 73000 | L33: =IF(K33<>"",24000+K33,24000) | Q33: 31 | R33: P CEBALLOS 8134 | S33: 102000 | T33: 4500 | U33: 2 | V33: 17/03/2026
B34: CHICLANA 72325 | C34: 2 | H34: 29000 | I34: 29000 | L34: =IF(K34<>"",2000+K34,2000) | Q34: 32 | R34: ROTI SAN LORENZO | S34: 98000 | T34: 23000 | U34: 1 | V34: 15/04/2026
B35: ALMONACID 3637 | C35: 1 | H35: 21000 | I35: 21000 | L35: =IF(K35<>"",7500+K35,7500) | Q35: 33 | R35: FRENCH BIS 2000 GONZA TORRI | S35: 97000 | T35: 37000 | U35: 1 | V35: 07/03/2026
B36: PANA ALBERTI | E36: 1 | H36: 72000 | I36: 72000 | L36: =IF(K36<>"",23000+K36,23000) | Q36: 34 | R36: ROTI VIEYTES | S36: 95000 | T36: 5000 | U36: 2 | V36: 17/04/2026
B37: ALBERTI 5200 | C37: 1 | H37: 20000 | J37: 20000 | L37: =IF(K37<>"",6500+K37,6500) | Q37: 35 | R37: BERUTI 3850 | S37: 91500 | T37: 16500 | U37: 1 | V37: 26/03/2026
A38: 46085 | B38: PANA GORRITI 4600 | E38: 1 | H38: 74000 | I38: 74000 | L38: =IF(K38<>"",25000+K38,25000) | Q38: 36 | R38: ALBERTI 4930 | S38: 91000 | T38: 29300 | U38: 2 | V38: 24/03/2026
B39: SAVEDRA 10125 | E39: 1 | H39: 79000 | J39: 79000 | L39: =IF(K39<>"",30000+K39,30000) | Q39: 37 | R39: NOGALES 2412 | S39: 83000 | T39: 23000 | U39: 1 | V39: 23/03/2026
B40: ROTI ZEBALLOS | C40: 2 | H40: 38000 | I40: 38000 | L40: =IF(K40<>"",11000+K40,11000) | Q40: 38 | R40: JOSE MONTEVERA | S40: 83000 | T40: 23000 | U40: 1 | V40: 18/03/2026
...

Sheet Abril
A1: VENTAS — ABRIL 2026 | Q1: 🏆 RANKING ABRIL
A2: ⚠ El nombre del cliente debe ser EXACTAMENTE igual siempre · La ganancia se calcula con el costo vigente a la fecha | Q2: # | R2: Cliente | S2: Facturado | T2: Ganancia | U2: Pedidos | V2: Últ. compra
Q3: 🥇 | R3: AZCUENAGA 5023 | S3: 475000 | T3: 100000 | U3: 4 | V3: 20/04/2026
A4: FECHA | B4: CLIENTE / DIRECCIÓN | C4: 10 | D4: 15 | E4: 45 | F4: YERBA | G4: AGUA | H4: VALOR ($) | I4: EFECTIVO ($) | J4: TRANSFER ($) | K4: ENVASE ($) | L4: GANANCIA ($) | N4: RESUMEN ABRIL | Q4: 🥈 | R4: FILOMENA | S4: 437000 | T4: 152000 | U4: 10 | V4: 20/04/2026
A5: 46113 | B5: DOMINGO SILVA 4217 | C5: 2 | D5: 1 | H5: 66500 | J5: 66500 | L5: =IF(K5<>"",14000+K5,14000) | N5: TOTAL 10 | O5: =IFERROR(SUM(C5:C700),0) | Q5: 🥉 | R5: OTNIEL | S5: 415300 | T5: 152650 | U5: 6 | V5: 16/04/2026
B6: MAMA NICO BUSTO | C6: 1 | F6: 10 | H6: 61000 | J6: 61000 | L6: =IF(K6<>"",23000+K6,23000) | N6: TOTAL 15 | O6: =IFERROR(SUM(D5:D700),0) | Q6: 4 | R6: LUCHO | S6: 411000 | T6: 94300 | U6: 10 | V6: 20/04/2026
B7: PANA VIEYTES 4500 | E7: 1 | H7: 78000 | J7: 78000 | L7: =IF(K7<>"",18000+K7,18000) | N7: TOTAL 45 | O7: =IFERROR(SUM(E5:E700),0) | Q7: 5 | R7: CAREN | S7: 328000 | T7: 88000 | U7: 4 | V7: 20/04/2026
B8: OTNIEL | G8: 3 | H8: 16500 | J8: 16500 | L8: =IF(K8<>"",13950+K8,13950) | N8: TOTAL YERBA | O8: =IFERROR(SUM(F5:F700),0) | Q8: 6 | R8: EXE | S8: 328000 | T8: 88000 | U8: 4 | V8: 19/04/2026
B9: M ZAPATA 2101 | C9: 2 | H9: 39000 | I9: 39000 | L9: =IF(K9<>"",9000+K9,9000) | N9: TOTAL AGUA | O9: =IFERROR(SUM(G5:G700),0) | Q9: 7 | R9: DANA | S9: 324000 | T9: 69000 | U9: 5 | V9: 22/04/2026
B10: LUCHO | C10: 1 | H10: 19000 | J10: 19000 | L10: =IF(K10<>"",4000+K10,4000) | Q10: 8 | R10: BRASERIA | S10: 249000 | T10: 69000 | U10: 3 | V10: 18/04/2026
B11: ALBERTI 5570 | E11: 2 | H11: 166000 | J11: 166000 | L11: =IF(K11<>"",46000+K11,46000) | N11: FACTURACIÓN | O11: =IFERROR(SUM(H5:H700),0) | Q11: 9 | R11: PANA ALBERTI | S11: 246000 | T11: 66000 | U11: 3 | V11: 22/04/2026
B12: ROTI SAN LORENZO | C12: 2 | D12: 1 | H12: 84000 | J12: 84000 | L12: =IF(K12<>"",31500+K12,31500) | N12: GANANCIA | O12: =IFERROR(SUM(L5:L700),0) | Q12: 10 | R12: PANA VIEYTES 4500 | S12: 234000 | T12: 54000 | U12: 3 | V12: 16/04/2026
B13: LUCHIO | G13: 1 | H13: 6000 | J13: 6000 | L13: =IF(K13<>"",5150+K13,5150) | N13: % GANANCIA | O13: =IFERROR(SUM(L5:L700)/SUM(H5:H700),0) | Q13: 11 | R13: ROTI SAN LORENZO | S13: 201000 | T13: 73500 | U13: 2 | V13: 15/04/2026
B14: GENEIRO 8200 | D14: 1 | H14: 39000 | I14: 39000 | L14: =IF(K14<>"",16500+K14,16500) | Q14: 12 | R14: SABOREAR | S14: 193500 | T14: 58500 | U14: 5 | V14: 22/04/2026
B15: FILOMENA | C15: 2 | H15: 46000 | J15: 46000 | L15: =IF(K15<>"",16000+K15,16000) | N15: EFECTIVO | O15: =IFERROR(SUM(I5:I700),0) | Q15: 13 | R15: ROTI VIEYTES | S15: 183000 | T15: 48000 | U15: 3 | V15: 17/04/2026
B16: SABOREAR | C16: 1 | H16: 22500 | J16: 22500 | L16: =IF(K16<>"",7500+K16,7500) | N16: TRANSFERENCIA | O16: =IFERROR(SUM(J5:J700),0) | Q16: 14 | R16: TERE | S16: 172000 | T16: 52000 | U16: 1 | V16: 02/04/2026
B17: MITRE 4930 | C17: 1 | H17: 27000 | I17: 27000 | L17: =IF(K17<>"",12000+K17,12000) | Q17: 15 | R17: ALBERTI 5570 | S17: 166000 | T17: 46000 | U17: 1 | V17: 01/04/2026
B18: POSTA EL TORO | C18: 2 | H18: 38000 | I18: 38000 | L18: =IF(K18<>"",8000+K18,8000) | N18: Nº VENTAS | O18: =IFERROR(COUNTA(B5:B700),0) | Q18: 16 | R18: PANA BERUTI 6400 | S18: 150000 | T18: 30000 | U18: 2 | V18: 22/04/2026
B19: LUCHO | C19: 1 | D19: 1 | H19: 47500 | J19: 47500 | L19: =IF(K19<>"",10000+K19,10000) | N19: DÍAS DEL MES | O19: 30 | Q19: 17 | R19: PANADERIA BAGUETE | S19: 150000 | T19: 30000 | U19: 2 | V19: 22/04/2026
B20: LA MADRID 7175 | D20: 1 | H20: 39000 | J20: 39000 | L20: =IF(K20<>"",16500+K20,16500) | Q20: 18 | R20: DOMINGO SILVA 4217 | S20: 142500 | T20: 30000 | U20: 2 | V20: 19/04/2026
B21: ROTI ARISTOBULO 5401 | D21: 1 | H21: 33500 | I21: 33500 | L21: =IF(K21<>"",11000+K21,11000) | N21: OBJETIVO ($) | Q21: 19 | R21: PANA BERUTI 3850 | S21: 142000 | T21: 37000 | U21: 1 | V21: 08/04/2026
A22: 46114 | B22: GABOTO 8168 | E22: 1 | H22: 83000 | J22: 83000 | L22: =IF(K22<>"",23000+K22,23000) | N22: DIFERENCIA | O22: =IFERROR(SUM(L5:L700)-N21,0) | Q22: 20 | R22: SANDRA | S22: 141000 | T22: 34300 | U22: 3 | V22: 16/04/2026
B23: AZCUENAGA 5023 | C23: 7 | H23: 133000 | J23: 133000 | L23: =IF(K23<>"",28000+K23,28000) | Q23: 21 | R23: DUSSO 7678 | S23: 133000 | T23: 28000 | U23: 1 | V23: 04/04/2026
B24: OTNIEL | C24: 1 | D24: 1 | H24: 57000 | J24: 57000 | L24: =IF(K24<>"",19500+K24,19500) | N24: KG BUTANO | O24: =IFERROR((SUM(C5:C700)*10)+(SUM(D5:D700)*15),0) | Q24: 22 | R24: LARGUIA 7287 | S24: 132000 | T24: 42000 | U24: 1 | V24: 20/04/2026
B25: LINIERS 3735 | C25: 1 | H25: 26000 | I25: 26000 | L25: =IF(K25<>"",11000+K25,11000) | N25: KG PROPANO | O25: =IFERROR(SUM(E5:E700)*45,0) | Q25: 23 | R25: ROTI AGUADO | S25: 115500 | T25: 33000 | U25: 2 | V25: 17/04/2026
B26: SIRLAKI | E26: 1 | H26: 80000 | J26: 80000 | L26: =IF(K26<>"",20000+K26,20000) | N26: KG TOTAL | O26: =IFERROR(O24+O25,0) | Q26: 24 | R26: GOLRD BURGER | S26: 115000 | T26: 40000 | U26: 1 | V26: 04/04/2026
B27: DANA | C27: 3 | H27: 57000 | I27: 57000 | L27: =IF(K27<>"",12000+K27,12000) | Q27: 25 | R27: COGORNP 5520 | S27: 114000 | T27: 24000 | U27: 1 | V27: 18/04/2026
B28: CASTELLI 2219 | C28: 1 | H28: 27000 | J28: 27000 | L28: =IF(K28<>"",12000+K28,12000) | N28: TICKET PROM. VENTA | O28: =IFERROR(SUM(H5:H700)/COUNTA(B5:B700),0) | Q28: 26 | R28: VIANDAS JORGE | S28: 110000 | T28: 35000 | U28: 5 | V28: 20/04/2026
B29: TERE | E29: 2 | H29: 172000 | I29: 86000 | J29: 86000 | L29: =IF(K29<>"",52000+K29,52000) | N29: TICKET PROM. GANANCIA | O29: =IFERROR(SUM(L5:L700)/COUNTA(B5:B700),0) | Q29: 27 | R29: DANTE | S29: 108000 | T29: 48000 | U29: 2 | V29: 12/04/2026
B30: TACUARI 5717 | C30: 1 | H30: 25000 | J30: 25000 | L30: =IF(K30<>"",10000+K30,10000) | Q30: 28 | R30: PORKIS | S30: 105000 | T30: 30000 | U30: 2 | V30: 19/04/2026
B31: BAIGORRIA 9351 | E31: 1 | H31: 90000 | I31: 90000 | L31: =IF(K31<>"",30000+K31,30000) | Q31: 29 | R31: CANCHA RIVADAVIA | S31: 105000 | T31: 30000 | U31: 1 | V31: 11/04/2026
B32: EXE | E32: 1 | H32: 82000 | J32: 82000 | L32: =IF(K32<>"",22000+K32,22000) | Q32: 30 | R32: GARMENDIA 9250 | S32: 102000 | T32: 40300 | U32: 2 | V32: 17/04/2026
B33: NACHO | C33: 1 | D33: 1 | H33: 56500 | I33: 56500 | L33: =IF(K33<>"",19000+K33,19000) | Q33: 31 | R33: POSTA COLASTINE | S33: 100000 | T33: 25000 | U33: 1 | V33: 04/04/2026
B34: GABOTO 7298 | D34: 1 | H34: 39000 | I34: 39000 | L34: =IF(K34<>"",16500+K34,16500) | Q34: 32 | R34: FREIRE 6181 | S34: 96000 | T34: 36000 | U34: 1 | V34: 06/04/2026
B35: GOROSTIAGA 4619 | E35: 1 | H35: 88000 | J35: 88000 | L35: =IF(K35<>"",28000+K35,28000) | Q35: 33 | R35: GASTON AMARAL | S35: 95000 | T35: 30400 | U35: 1 | V35: 15/04/2026
B36: LARGUIA 6924 | C36: 1 | H36: 25000 | I36: 25000 | L36: =IF(K36<>"",10000+K36,10000) | Q36: 34 | R36: ESTRADA 2198 | S36: 95000 | T36: 35000 | U36: 1 | V36: 10/04/2026
B37: BELNGRANO 3881 | C37: 2 | H37: 54000 | J37: 54000 | L37: =IF(K37<>"",24000+K37,24000) | Q37: 35 | R37: PAULO | S37: 94000 | T37: 19000 | U37: 2 | V37: 13/04/2026
A38: 46115 | B38: PAVON 2124 | D38: 1 | H38: 39000 | I38: 39000 | L38: =IF(K38<>"",16500+K38,16500) | Q38: 36 | R38: SAVEDRA 10125 | S38: 92000 | T38: 32000 | U38: 1 | V38: 09/04/2026
B39: D SILVA 4217 | C39: 2 | H39: 38000 | J39: 38000 | L39: =IF(K39<>"",8000+K39,8000) | Q39: 37 | R39: ILGATO | S39: 92000 | T39: 32000 | U39: 1 | V39: 12/04/2026
B40: ROTI ROCA 6371 | C40: 1 | H40: 25000 | J40: 25000 | L40: =IF(K40<>"",10000+K40,10000) | Q40: 38 | R40: EUROPA 9186 | S40: 90000 | T40: 30000 | U40: 1 | V40: 04/04/2026
...

Sheet Junio
A1: VENTAS — JUNIO 2026
A2: Datos cargados por Sistema Galiano
A4: FECHA | B4: CLIENTE | C4: 10 | D4: 15 | E4: 45 | F4: YERBA | G4: AGUA/BIDON | H4: VALOR ($) | I4: EFECTIVO ($) | J4: TRANSFER ($) | K4: ENVASE ($) | L4: GANANCIA ($)
A5: 2026-06-01 | B5: DALLAS 6761 | E5: 1 | H5: 98000 | J5: 98000 | L5: 29000
B6: CHICLANA 6630 | C6: 1 | H6: 26000 | J6: 26000 | L6: 9000
B7: BLAS PARERA 6372 | E7: 1 | H7: 93000 | J7: 93000 | L7: 24000
B8: PANA BERUTI 6700 | E8: 1 | H8: 88000 | I8: 88000 | L8: 19000
B9: SAN MARTIN 9308 | D9: 1 | H9: 41500 | I9: 41500 | L9: 16000
B10: LARGUIA 9355 | E10: 1 | H10: 96000 | J10: 96000 | L10: 27000
B11: PANA VIEYTES 4500 | C11: 1 | E11: 1 | H11: 113000 | J11: 113000 | L11: 27000
B12: MARCIAL CANDIOTI 5359 | C12: 1 | H12: 28000 | I12: 28000 | L12: 11000
B13: MATEU 4059 | D13: 1 | H13: 37000 | I13: 37000 | L13: 11500
B14: LAVAISE 3786 | C14: 1 | D14: 1 | H14: 69000 | J14: 69000 | L14: 26500
B15: CASANELLO 3463 | C15: 1 | H15: 28000 | J15: 28000 | L15: 11000
B16: LUCHO | D16: 1 | H16: 35000 | J16: 35000 | L16: 9500
B17: 9 DE JULIO 6810 | C17: 1 | H17: 27500 | I17: 27500 | L17: 10500
B18: FILOMENA | C18: 3 | H18: 79500 | J18: 79500 | L18: 28500
B19: PEDRO ESPINOSA 3169 | E19: 1 | H19: 92000 | I19: 92000 | L19: 23000
A20: 2026-06-02 | B20: ESTRADA 2815 | C20: 1 | H20: 28000 | I20: 28000 | L20: 11000
B21: PASAJE PARAGUAY 10333 | E21: 1 | H21: 96000 | J21: 96000 | L21: 27000
B22: CHICLANA 7325 | C22: 1 | H22: 22500 | J22: 22500 | L22: 5500
B23: MADAME CHEESE | D23: 1 | H23: 38500 | J23: 38500 | L23: 13000
B24: VIANDAS JORGE | C24: 1 | H24: 25000 | I24: 25000 | L24: 8000
B25: IGUALDAD | C25: 1 | H25: 27000 | J25: 27000 | L25: 10000
B26: ROTI ARISTOBULO | C26: 1 | D26: 1 | H26: 65000 | J26: 65000 | L26: 22500
B27: DAVID LEIVA Y ALBERTI | C27: 1 | H27: 27000 | I27: 27000 | L27: 10000
B28: PRIMERO DE MAYO 1605 | D28: 1 | H28: 42000 | I28: 42000 | L28: 16500
B29: PIEDRABUENA 6450 | E29: 1 | H29: 93000 | J29: 93000 | L29: 24000
B30: BRASIL 4871 | C30: 1 | H30: 28000 | I30: 28000 | L30: 11000
B31: SERVANDO BAYO 7250 | C31: 1 | H31: 27000 | I31: 27000 | L31: 10000
B32: ANGELA LAMADRID 7500 | C32: 1 | H32: 28000 | I32: 28000 | L32: 11000
B33: LAMADRID 1086 | C33: 1 | H33: 27000 | J33: 27000 | L33: 10000
B34: CALLE CONFUNE 5070 | E34: 1 | H34: 96000 | J34: 96000 | L34: 27000
B35: COLODRERO 1258 | E35: 1 | H35: 89000 | J35: 89000 | L35: 20000
B36: NOGALES 2426 | C36: 1 | H36: 28000 | J36: 28000 | L36: 11000
B37: BERUTI 6400 | E37: 1 | H37: 96000 | I37: 96000 | L37: 27000
B38: NAMUNCURA 4436 | E38: 1 | H38: 96000 | J38: 96000 | L38: 27000
B39: ALSINA 7980 | C39: 1 | H39: 28000 | I39: 28000 | L39: 11000
B40: GARMENDIA 9249 | D40: 1 | H40: 41500 | J40: 41500 | L40: 16000
B41: NACHO CUEVA | C41: 1 | H41: 25500 | I41: 25500 | L41: 8500
...

Sheet Mayo
A1: VENTAS — MAYO 2026
A2: ⚠ El nombre del cliente debe ser EXACTAMENTE igual siempre · La ganancia se calcula con el costo vigente a la fecha
A4: FECHA | B4: CLIENTE / DIRECCIÓN | C4: 10 | D4: 15 | E4: 45 | F4: YERBA | G4: AGUA | H4: VALOR ($) | I4: EFECTIVO ($) | J4: TRANSFER ($) | K4: ENVASE ($) | L4: GANANCIA ($) | N4: RESUMEN MAYO
A5: 46143 | B5: 5TO PASAJE 9681 | E5: 1 | H5: 95000 | J5: 95000 | L5: =IF(K5<>"",35000+K5,35000) | N5: TOTAL 10 | O5: =IFERROR(SUM(C5:C700),0)
B6: PIEDRABUENA 4506 | E6: 1 | H6: 91000 | J6: 91000 | L6: =IF(K6<>"",31000+K6,31000) | N6: TOTAL 15 | O6: =IFERROR(SUM(D5:D700),0)
B7: ALBERTI 5303 | C7: 1 | H7: 25000 | I7: 25000 | L7: =IF(K7<>"",10000+K7,10000) | N7: TOTAL 45 | O7: =IFERROR(SUM(E5:E700),0)
B8: LUCHO | C8: 1 | D8: 1 | H8: 47500 | I8: 47500 | L8: =IF(K8<>"",10000+K8,10000) | N8: TOTAL YERBA | O8: =IFERROR(SUM(F5:F700),0)
B9: CALLEJON ROCA 2622 | C9: 1 | H9: 27000 | I9: 27000 | L9: =IF(K9<>"",12000+K9,12000) | N9: TOTAL AGUA | O9: =IFERROR(SUM(G5:G700),0)
B10: 4 DE ENERO 6652 | C10: 1 | H10: 27000 | I10: 27000 | L10: =IF(K10<>"",12000+K10,12000)
B11: GUANELLA 4883 | D11: 1 | H11: 37500 | J11: 37500 | L11: =IF(K11<>"",15000+K11,15000) | N11: FACTURACIÓN | O11: =IFERROR(SUM(H5:H700),0)
B12: CARRANZA 8275 | C12: 1 | H12: 26000 | J12: 26000 | L12: =IF(K12<>"",11000+K12,11000) | N12: GANANCIA | O12: =IFERROR(SUM(L5:L700),0)
B13: GENEIRO 8249 | C13: 1 | H13: 26000 | J13: 26000 | L13: =IF(K13<>"",11000+K13,11000) | N13: % GANANCIA | O13: =IFERROR(SUM(L5:L700)/SUM(H5:H700),0)
B14: PANA ALBERTI | E14: 1 | H14: 82000 | I14: 82000 | L14: =IF(K14<>"",22000+K14,22000)
B15: BAGUETTE | E15: 1 | H15: 75000 | J15: 75000 | L15: =IF(K15<>"",15000+K15,15000) | N15: EFECTIVO | O15: =IFERROR(SUM(I5:I700),0)
B16: RIVADAVIA 8280 | E16: 1 | H16: 92000 | J16: 92000 | L16: =IF(K16<>"",32000+K16,32000) | N16: TRANSFERENCIA | O16: =IFERROR(SUM(J5:J700),0)
B17: LUCHO | C17: 1 | D17: 1 | H17: 47500 | J17: 47500 | L17: =IF(K17<>"",10000+K17,10000)
B18: MARCIAL CANDIOTI 6281 | D18: 1 | H18: 39000 | I18: 39000 | L18: =IF(K18<>"",16500+K18,16500) | N18: Nº VENTAS | O18: =IFERROR(COUNTA(B5:B700),0)
B19: BRASERIA | E19: 1 | H19: 83000 | J19: 83000 | L19: =IF(K19<>"",23000+K19,23000) | N19: DÍAS DEL MES | O19: 31
A20: 46144 | B20: RIVADAVIA JUNIORS | C20: 2 | H20: 52000 | I20: 52000 | L20: =IF(K20<>"",22000+K20,22000)
B21: URQUIZA 9309 | C21: 2 | D21: 1 | H21: 68500 | J21: 68500 | L21: =IF(K21<>"",16000+K21,16000) | N21: OBJETIVO ($)
B22: BEATRIZ | G22: 2 | H22: 12000 | J22: 12000 | L22: =IF(K22<>"",10300+K22,10300) | N22: DIFERENCIA | O22: =IFERROR(SUM(L5:L700)-N21,0)
B23: LAVALLE 4859 | C23: 1 | H23: 26000 | I23: 26000 | L23: =IF(K23<>"",11000+K23,11000)
B24: DOMINGO SILVA 4217 | C24: 1 | D24: 1 | H24: 47500 | J24: 47500 | L24: =IF(K24<>"",10000+K24,10000) | N24: KG BUTANO | O24: =IFERROR((SUM(C5:C700)*10)+(SUM(D5:D700)*15),0)
B25: ALSINA 7981 | E25: 1 | H25: 84000 | I25: 84000 | L25: =IF(K25<>"",24000+K25,24000) | N25: KG PROPANO | O25: =IFERROR(SUM(E5:E700)*45,0)
B26: ROTI SAN LORENZO | C26: 2 | D26: 1 | H26: 85000 | J26: 85000 | L26: =IF(K26<>"",32500+K26,32500) | N26: KG TOTAL | O26: =IFERROR(O24+O25,0)
B27: OTNIEL | D27: 1 | E27: 1 | H27: 115000 | I27: 115000 | L27: =IF(K27<>"",32500+K27,32500)
B28: MARCE DUSO | C28: 3 | H28: 57000 | I28: 57000 | L28: =IF(K28<>"",12000+K28,12000) | N28: TICKET PROM. VENTA | O28: =IFERROR(SUM(H5:H700)/COUNTA(B5:B700),0)
B29: VIÑAS 9420 | E29: 1 | H29: 92000 | J29: 92000 | L29: =IF(K29<>"",32000+K29,32000) | N29: TICKET PROM. GANANCIA | O29: =IFERROR(SUM(L5:L700)/COUNTA(B5:B700),0)
B30: VIANDAS JORGE | C30: 1 | H30: 22000 | I30: 22000 | L30: =IF(K30<>"",7000+K30,7000)
B31: JOSE CIBILS 6789 | E31: 1 | H31: 91000 | I31: 91000 | L31: =IF(K31<>"",31000+K31,31000)
B32: RICARDO ALDAO 3082 | C32: 1 | H32: 26000 | I32: 26000 | L32: =IF(K32<>"",11000+K32,11000)
B33: FLORENCIO FERNANDEZ 6196 | C33: 10 | H33: 185000 | J33: 185000 | L33: =IF(K33<>"",35000+K33,35000)
B34: FLORES 1 CANCHITA | C34: 1 | H34: 26000 | I34: 26000 | L34: =IF(K34<>"",11000+K34,11000)
B35: GORRITI 4661 | C35: 1 | H35: 26000 | J35: 26000 | L35: =IF(K35<>"",11000+K35,11000)
B36: AZOPARDO Y FLORENCIO SANCHEZ | D36: 1 | H36: 35500 | J36: 35500 | L36: =IF(K36<>"",13000+K36,13000)
B37: CALLE 14 3363 | E37: 1 | H37: 91000 | J37: 91000 | L37: =IF(K37<>"",31000+K37,31000)
B38: REMEDIO DE ESCALADA | E38: 2 | H38: 180000 | I38: 180000 | L38: =IF(K38<>"",60000+K38,60000)
B39: LUCHO | C39: 1 | D39: 1 | H39: 47500 | J39: 47500 | L39: =IF(K39<>"",10000+K39,10000)
B40: SAN JUAN 1963 | E40: 1 | H40: 91000 | J40: 91000 | L40: =IF(K40<>"",31000+K40,31000)
B41: URQUIZA 9309 | C41: 3 | D41: 1 | H41: 88000 | J41: 88000 | L41: =IF(K41<>"",20500+K41,20500)
...

Sheet Julio
A1: VENTAS — JULIO 2026
A2: ⚠ El nombre del cliente debe ser EXACTAMENTE igual siempre · La ganancia se calcula con el costo vigente a la fecha
A4: FECHA | B4: CLIENTE / DIRECCIÓN | C4: 10 | D4: 15 | E4: 45 | F4: YERBA | G4: AGUA | H4: VALOR ($) | I4: EFECTIVO ($) | J4: TRANSFER ($) | K4: ENVASE ($) | L4: GANANCIA ($) | N4: RESUMEN JULIO
L5: =IF(K5<>"",(IF(H5="","",H5-(C5*COSTOS!$C$6+D5*COSTOS!$C$7+E5*COSTOS!$C$8+F5*COSTOS!$C$9+G5*COSTOS!$C$10)))+K5,IF(H5="","",H5-(C5*COSTOS!$C$6+D5*COSTOS!$C$7+E5*COSTOS!$C$8+F5*COSTOS!$C$9+G5*COSTOS!$C$10))) | N5: TOTAL 10 | O5: =IFERROR(SUM(C5:C700),0)
L6: =IF(K6<>"",(IF(H6="","",H6-(C6*COSTOS!$C$6+D6*COSTOS!$C$7+E6*COSTOS!$C$8+F6*COSTOS!$C$9+G6*COSTOS!$C$10)))+K6,IF(H6="","",H6-(C6*COSTOS!$C$6+D6*COSTOS!$C$7+E6*COSTOS!$C$8+F6*COSTOS!$C$9+G6*COSTOS!$C$10))) | N6: TOTAL 15 | O6: =IFERROR(SUM(D5:D700),0)
L7: =IF(K7<>"",(IF(H7="","",H7-(C7*COSTOS!$C$6+D7*COSTOS!$C$7+E7*COSTOS!$C$8+F7*COSTOS!$C$9+G7*COSTOS!$C$10)))+K7,IF(H7="","",H7-(C7*COSTOS!$C$6+D7*COSTOS!$C$7+E7*COSTOS!$C$8+F7*COSTOS!$C$9+G7*COSTOS!$C$10))) | N7: TOTAL 45 | O7: =IFERROR(SUM(E5:E700),0)
L8: =IF(K8<>"",(IF(H8="","",H8-(C8*COSTOS!$C$6+D8*COSTOS!$C$7+E8*COSTOS!$C$8+F8*COSTOS!$C$9+G8*COSTOS!$C$10)))+K8,IF(H8="","",H8-(C8*COSTOS!$C$6+D8*COSTOS!$C$7+E8*COSTOS!$C$8+F8*COSTOS!$C$9+G8*COSTOS!$C$10))) | N8: TOTAL YERBA | O8: =IFERROR(SUM(F5:F700),0)
L9: =IF(K9<>"",(IF(H9="","",H9-(C9*COSTOS!$C$6+D9*COSTOS!$C$7+E9*COSTOS!$C$8+F9*COSTOS!$C$9+G9*COSTOS!$C$10)))+K9,IF(H9="","",H9-(C9*COSTOS!$C$6+D9*COSTOS!$C$7+E9*COSTOS!$C$8+F9*COSTOS!$C$9+G9*COSTOS!$C$10))) | N9: TOTAL AGUA | O9: =IFERROR(SUM(G5:G700),0)
L10: =IF(K10<>"",(IF(H10="","",H10-(C10*COSTOS!$C$6+D10*COSTOS!$C$7+E10*COSTOS!$C$8+F10*COSTOS!$C$9+G10*COSTOS!$C$10)))+K10,IF(H10="","",H10-(C10*COSTOS!$C$6+D10*COSTOS!$C$7+E10*COSTOS!$C$8+F10*COSTOS!$C$9+G10*COSTOS!$C$10)))
L11: =IF(K11<>"",(IF(H11="","",H11-(C11*COSTOS!$C$6+D11*COSTOS!$C$7+E11*COSTOS!$C$8+F11*COSTOS!$C$9+G11*COSTOS!$C$10)))+K11,IF(H11="","",H11-(C11*COSTOS!$C$6+D11*COSTOS!$C$7+E11*COSTOS!$C$8+F11*COSTOS!$C$9+G11*COSTOS!$C$10))) | N11: FACTURACIÓN | O11: =IFERROR(SUM(H5:H700),0)
L12: =IF(K12<>"",(IF(H12="","",H12-(C12*COSTOS!$C$6+D12*COSTOS!$C$7+E12*COSTOS!$C$8+F12*COSTOS!$C$9+G12*COSTOS!$C$10)))+K12,IF(H12="","",H12-(C12*COSTOS!$C$6+D12*COSTOS!$C$7+E12*COSTOS!$C$8+F12*COSTOS!$C$9+G12*COSTOS!$C$10))) | N12: GANANCIA | O12: =IFERROR(SUM(L5:L700),0)
L13: =IF(K13<>"",(IF(H13="","",H13-(C13*COSTOS!$C$6+D13*COSTOS!$C$7+E13*COSTOS!$C$8+F13*COSTOS!$C$9+G13*COSTOS!$C$10)))+K13,IF(H13="","",H13-(C13*COSTOS!$C$6+D13*COSTOS!$C$7+E13*COSTOS!$C$8+F13*COSTOS!$C$9+G13*COSTOS!$C$10))) | N13: % GANANCIA | O13: =IFERROR(SUM(L5:L700)/SUM(H5:H700),0)
L14: =IF(K14<>"",(IF(H14="","",H14-(C14*COSTOS!$C$6+D14*COSTOS!$C$7+E14*COSTOS!$C$8+F14*COSTOS!$C$9+G14*COSTOS!$C$10)))+K14,IF(H14="","",H14-(C14*COSTOS!$C$6+D14*COSTOS!$C$7+E14*COSTOS!$C$8+F14*COSTOS!$C$9+G14*COSTOS!$C$10)))
L15: =IF(K15<>"",(IF(H15="","",H15-(C15*COSTOS!$C$6+D15*COSTOS!$C$7+E15*COSTOS!$C$8+F15*COSTOS!$C$9+G15*COSTOS!$C$10)))+K15,IF(H15="","",H15-(C15*COSTOS!$C$6+D15*COSTOS!$C$7+E15*COSTOS!$C$8+F15*COSTOS!$C$9+G15*COSTOS!$C$10))) | N15: EFECTIVO | O15: =IFERROR(SUM(I5:I700),0)
L16: =IF(K16<>"",(IF(H16="","",H16-(C16*COSTOS!$C$6+D16*COSTOS!$C$7+E16*COSTOS!$C$8+F16*COSTOS!$C$9+G16*COSTOS!$C$10)))+K16,IF(H16="","",H16-(C16*COSTOS!$C$6+D16*COSTOS!$C$7+E16*COSTOS!$C$8+F16*COSTOS!$C$9+G16*COSTOS!$C$10))) | N16: TRANSFERENCIA | O16: =IFERROR(SUM(J5:J700),0)
L17: =IF(K17<>"",(IF(H17="","",H17-(C17*COSTOS!$C$6+D17*COSTOS!$C$7+E17*COSTOS!$C$8+F17*COSTOS!$C$9+G17*COSTOS!$C$10)))+K17,IF(H17="","",H17-(C17*COSTOS!$C$6+D17*COSTOS!$C$7+E17*COSTOS!$C$8+F17*COSTOS!$C$9+G17*COSTOS!$C$10)))
L18: =IF(K18<>"",(IF(H18="","",H18-(C18*COSTOS!$C$6+D18*COSTOS!$C$7+E18*COSTOS!$C$8+F18*COSTOS!$C$9+G18*COSTOS!$C$10)))+K18,IF(H18="","",H18-(C18*COSTOS!$C$6+D18*COSTOS!$C$7+E18*COSTOS!$C$8+F18*COSTOS!$C$9+G18*COSTOS!$C$10))) | N18: Nº VENTAS | O18: =IFERROR(COUNTA(B5:B700),0)
L19: =IF(K19<>"",(IF(H19="","",H19-(C19*COSTOS!$C$6+D19*COSTOS!$C$7+E19*COSTOS!$C$8+F19*COSTOS!$C$9+G19*COSTOS!$C$10)))+K19,IF(H19="","",H19-(C19*COSTOS!$C$6+D19*COSTOS!$C$7+E19*COSTOS!$C$8+F19*COSTOS!$C$9+G19*COSTOS!$C$10))) | N19: DÍAS DEL MES | O19: 31
L20: =IF(K20<>"",(IF(H20="","",H20-(C20*COSTOS!$C$6+D20*COSTOS!$C$7+E20*COSTOS!$C$8+F20*COSTOS!$C$9+G20*COSTOS!$C$10)))+K20,IF(H20="","",H20-(C20*COSTOS!$C$6+D20*COSTOS!$C$7+E20*COSTOS!$C$8+F20*COSTOS!$C$9+G20*COSTOS!$C$10)))
L21: =IF(K21<>"",(IF(H21="","",H21-(C21*COSTOS!$C$6+D21*COSTOS!$C$7+E21*COSTOS!$C$8+F21*COSTOS!$C$9+G21*COSTOS!$C$10)))+K21,IF(H21="","",H21-(C21*COSTOS!$C$6+D21*COSTOS!$C$7+E21*COSTOS!$C$8+F21*COSTOS!$C$9+G21*COSTOS!$C$10))) | N21: OBJETIVO ($)
L22: =IF(K22<>"",(IF(H22="","",H22-(C22*COSTOS!$C$6+D22*COSTOS!$C$7+E22*COSTOS!$C$8+F22*COSTOS!$C$9+G22*COSTOS!$C$10)))+K22,IF(H22="","",H22-(C22*COSTOS!$C$6+D22*COSTOS!$C$7+E22*COSTOS!$C$8+F22*COSTOS!$C$9+G22*COSTOS!$C$10))) | N22: DIFERENCIA | O22: =IFERROR(SUM(L5:L700)-N21,0)
L23: =IF(K23<>"",(IF(H23="","",H23-(C23*COSTOS!$C$6+D23*COSTOS!$C$7+E23*COSTOS!$C$8+F23*COSTOS!$C$9+G23*COSTOS!$C$10)))+K23,IF(H23="","",H23-(C23*COSTOS!$C$6+D23*COSTOS!$C$7+E23*COSTOS!$C$8+F23*COSTOS!$C$9+G23*COSTOS!$C$10)))
L24: =IF(K24<>"",(IF(H24="","",H24-(C24*COSTOS!$C$6+D24*COSTOS!$C$7+E24*COSTOS!$C$8+F24*COSTOS!$C$9+G24*COSTOS!$C$10)))+K24,IF(H24="","",H24-(C24*COSTOS!$C$6+D24*COSTOS!$C$7+E24*COSTOS!$C$8+F24*COSTOS!$C$9+G24*COSTOS!$C$10)))
L25: =IF(K25<>"",(IF(H25="","",H25-(C25*COSTOS!$C$6+D25*COSTOS!$C$7+E25*COSTOS!$C$8+F25*COSTOS!$C$9+G25*COSTOS!$C$10)))+K25,IF(H25="","",H25-(C25*COSTOS!$C$6+D25*COSTOS!$C$7+E25*COSTOS!$C$8+F25*COSTOS!$C$9+G25*COSTOS!$C$10)))
L26: =IF(K26<>"",(IF(H26="","",H26-(C26*COSTOS!$C$6+D26*COSTOS!$C$7+E26*COSTOS!$C$8+F26*COSTOS!$C$9+G26*COSTOS!$C$10)))+K26,IF(H26="","",H26-(C26*COSTOS!$C$6+D26*COSTOS!$C$7+E26*COSTOS!$C$8+F26*COSTOS!$C$9+G26*COSTOS!$C$10)))
L27: =IF(K27<>"",(IF(H27="","",H27-(C27*COSTOS!$C$6+D27*COSTOS!$C$7+E27*COSTOS!$C$8+F27*COSTOS!$C$9+G27*COSTOS!$C$10)))+K27,IF(H27="","",H27-(C27*COSTOS!$C$6+D27*COSTOS!$C$7+E27*COSTOS!$C$8+F27*COSTOS!$C$9+G27*COSTOS!$C$10)))
L28: =IF(K28<>"",(IF(H28="","",H28-(C28*COSTOS!$C$6+D28*COSTOS!$C$7+E28*COSTOS!$C$8+F28*COSTOS!$C$9+G28*COSTOS!$C$10)))+K28,IF(H28="","",H28-(C28*COSTOS!$C$6+D28*COSTOS!$C$7+E28*COSTOS!$C$8+F28*COSTOS!$C$9+G28*COSTOS!$C$10)))
L29: =IF(K29<>"",(IF(H29="","",H29-(C29*COSTOS!$C$6+D29*COSTOS!$C$7+E29*COSTOS!$C$8+F29*COSTOS!$C$9+G29*COSTOS!$C$10)))+K29,IF(H29="","",H29-(C29*COSTOS!$C$6+D29*COSTOS!$C$7+E29*COSTOS!$C$8+F29*COSTOS!$C$9+G29*COSTOS!$C$10))) | O29: =IFERROR(SUM(L5:L700)/COUNTA(B5:B700),0)
L30: =IF(K30<>"",(IF(H30="","",H30-(C30*COSTOS!$C$6+D30*COSTOS!$C$7+E30*COSTOS!$C$8+F30*COSTOS!$C$9+G30*COSTOS!$C$10)))+K30,IF(H30="","",H30-(C30*COSTOS!$C$6+D30*COSTOS!$C$7+E30*COSTOS!$C$8+F30*COSTOS!$C$9+G30*COSTOS!$C$10)))
L31: =IF(K31<>"",(IF(H31="","",H31-(C31*COSTOS!$C$6+D31*COSTOS!$C$7+E31*COSTOS!$C$8+F31*COSTOS!$C$9+G31*COSTOS!$C$10)))+K31,IF(H31="","",H31-(C31*COSTOS!$C$6+D31*COSTOS!$C$7+E31*COSTOS!$C$8+F31*COSTOS!$C$9+G31*COSTOS!$C$10)))
L32: =IF(K32<>"",(IF(H32="","",H32-(C32*COSTOS!$C$6+D32*COSTOS!$C$7+E32*COSTOS!$C$8+F32*COSTOS!$C$9+G32*COSTOS!$C$10)))+K32,IF(H32="","",H32-(C32*COSTOS!$C$6+D32*COSTOS!$C$7+E32*COSTOS!$C$8+F32*COSTOS!$C$9+G32*COSTOS!$C$10)))
L33: =IF(K33<>"",(IF(H33="","",H33-(C33*COSTOS!$C$6+D33*COSTOS!$C$7+E33*COSTOS!$C$8+F33*COSTOS!$C$9+G33*COSTOS!$C$10)))+K33,IF(H33="","",H33-(C33*COSTOS!$C$6+D33*COSTOS!$C$7+E33*COSTOS!$C$8+F33*COSTOS!$C$9+G33*COSTOS!$C$10)))
L34: =IF(K34<>"",(IF(H34="","",H34-(C34*COSTOS!$C$6+D34*COSTOS!$C$7+E34*COSTOS!$C$8+F34*COSTOS!$C$9+G34*COSTOS!$C$10)))+K34,IF(H34="","",H34-(C34*COSTOS!$C$6+D34*COSTOS!$C$7+E34*COSTOS!$C$8+F34*COSTOS!$C$9+G34*COSTOS!$C$10)))
L35: =IF(K35<>"",(IF(H35="","",H35-(C35*COSTOS!$C$6+D35*COSTOS!$C$7+E35*COSTOS!$C$8+F35*COSTOS!$C$9+G35*COSTOS!$C$10)))+K35,IF(H35="","",H35-(C35*COSTOS!$C$6+D35*COSTOS!$C$7+E35*COSTOS!$C$8+F35*COSTOS!$C$9+G35*COSTOS!$C$10)))
L36: =IF(K36<>"",(IF(H36="","",H36-(C36*COSTOS!$C$6+D36*COSTOS!$C$7+E36*COSTOS!$C$8+F36*COSTOS!$C$9+G36*COSTOS!$C$10)))+K36,IF(H36="","",H36-(C36*COSTOS!$C$6+D36*COSTOS!$C$7+E36*COSTOS!$C$8+F36*COSTOS!$C$9+G36*COSTOS!$C$10)))
L37: =IF(K37<>"",(IF(H37="","",H37-(C37*COSTOS!$C$6+D37*COSTOS!$C$7+E37*COSTOS!$C$8+F37*COSTOS!$C$9+G37*COSTOS!$C$10)))+K37,IF(H37="","",H37-(C37*COSTOS!$C$6+D37*COSTOS!$C$7+E37*COSTOS!$C$8+F37*COSTOS!$C$9+G37*COSTOS!$C$10)))
L38: =IF(K38<>"",(IF(H38="","",H38-(C38*COSTOS!$C$6+D38*COSTOS!$C$7+E38*COSTOS!$C$8+F38*COSTOS!$C$9+G38*COSTOS!$C$10)))+K38,IF(H38="","",H38-(C38*COSTOS!$C$6+D38*COSTOS!$C$7+E38*COSTOS!$C$8+F38*COSTOS!$C$9+G38*COSTOS!$C$10)))
L39: =IF(K39<>"",(IF(H39="","",H39-(C39*COSTOS!$C$6+D39*COSTOS!$C$7+E39*COSTOS!$C$8+F39*COSTOS!$C$9+G39*COSTOS!$C$10)))+K39,IF(H39="","",H39-(C39*COSTOS!$C$6+D39*COSTOS!$C$7+E39*COSTOS!$C$8+F39*COSTOS!$C$9+G39*COSTOS!$C$10)))
L40: =IF(K40<>"",(IF(H40="","",H40-(C40*COSTOS!$C$6+D40*COSTOS!$C$7+E40*COSTOS!$C$8+F40*COSTOS!$C$9+G40*COSTOS!$C$10)))+K40,IF(H40="","",H40-(C40*COSTOS!$C$6+D40*COSTOS!$C$7+E40*COSTOS!$C$8+F40*COSTOS!$C$9+G40*COSTOS!$C$10)))
L41: =IF(K41<>"",(IF(H41="","",H41-(C41*COSTOS!$C$6+D41*COSTOS!$C$7+E41*COSTOS!$C$8+F41*COSTOS!$C$9+G41*COSTOS!$C$10)))+K41,IF(H41="","",H41-(C41*COSTOS!$C$6+D41*COSTOS!$C$7+E41*COSTOS!$C$8+F41*COSTOS!$C$9+G41*COSTOS!$C$10)))
...

Sheet Agosto
A1: VENTAS — AGOSTO 2026
A2: ⚠ El nombre del cliente debe ser EXACTAMENTE igual siempre · La ganancia se calcula con el costo vigente a la fecha
A4: FECHA | B4: CLIENTE / DIRECCIÓN | C4: 10 | D4: 15 | E4: 45 | F4: YERBA | G4: AGUA | H4: VALOR ($) | I4: EFECTIVO ($) | J4: TRANSFER ($) | K4: ENVASE ($) | L4: GANANCIA ($) | N4: RESUMEN AGOSTO
L5: =IF(K5<>"",(IF(H5="","",H5-(C5*COSTOS!$C$6+D5*COSTOS!$C$7+E5*COSTOS!$C$8+F5*COSTOS!$C$9+G5*COSTOS!$C$10)))+K5,IF(H5="","",H5-(C5*COSTOS!$C$6+D5*COSTOS!$C$7+E5*COSTOS!$C$8+F5*COSTOS!$C$9+G5*COSTOS!$C$10))) | N5: TOTAL 10 | O5: =IFERROR(SUM(C5:C700),0)
L6: =IF(K6<>"",(IF(H6="","",H6-(C6*COSTOS!$C$6+D6*COSTOS!$C$7+E6*COSTOS!$C$8+F6*COSTOS!$C$9+G6*COSTOS!$C$10)))+K6,IF(H6="","",H6-(C6*COSTOS!$C$6+D6*COSTOS!$C$7+E6*COSTOS!$C$8+F6*COSTOS!$C$9+G6*COSTOS!$C$10))) | N6: TOTAL 15 | O6: =IFERROR(SUM(D5:D700),0)
L7: =IF(K7<>"",(IF(H7="","",H7-(C7*COSTOS!$C$6+D7*COSTOS!$C$7+E7*COSTOS!$C$8+F7*COSTOS!$C$9+G7*COSTOS!$C$10)))+K7,IF(H7="","",H7-(C7*COSTOS!$C$6+D7*COSTOS!$C$7+E7*COSTOS!$C$8+F7*COSTOS!$C$9+G7*COSTOS!$C$10))) | N7: TOTAL 45 | O7: =IFERROR(SUM(E5:E700),0)
L8: =IF(K8<>"",(IF(H8="","",H8-(C8*COSTOS!$C$6+D8*COSTOS!$C$7+E8*COSTOS!$C$8+F8*COSTOS!$C$9+G8*COSTOS!$C$10)))+K8,IF(H8="","",H8-(C8*COSTOS!$C$6+D8*COSTOS!$C$7+E8*COSTOS!$C$8+F8*COSTOS!$C$9+G8*COSTOS!$C$10))) | N8: TOTAL YERBA | O8: =IFERROR(SUM(F5:F700),0)
L9: =IF(K9<>"",(IF(H9="","",H9-(C9*COSTOS!$C$6+D9*COSTOS!$C$7+E9*COSTOS!$C$8+F9*COSTOS!$C$9+G9*COSTOS!$C$10)))+K9,IF(H9="","",H9-(C9*COSTOS!$C$6+D9*COSTOS!$C$7+E9*COSTOS!$C$8+F9*COSTOS!$C$9+G9*COSTOS!$C$10))) | N9: TOTAL AGUA | O9: =IFERROR(SUM(G5:G700),0)
L10: =IF(K10<>"",(IF(H10="","",H10-(C10*COSTOS!$C$6+D10*COSTOS!$C$7+E10*COSTOS!$C$8+F10*COSTOS!$C$9+G10*COSTOS!$C$10)))+K10,IF(H10="","",H10-(C10*COSTOS!$C$6+D10*COSTOS!$C$7+E10*COSTOS!$C$8+F10*COSTOS!$C$9+G10*COSTOS!$C$10)))
L11: =IF(K11<>"",(IF(H11="","",H11-(C11*COSTOS!$C$6+D11*COSTOS!$C$7+E11*COSTOS!$C$8+F11*COSTOS!$C$9+G11*COSTOS!$C$10)))+K11,IF(H11="","",H11-(C11*COSTOS!$C$6+D11*COSTOS!$C$7+E11*COSTOS!$C$8+F11*COSTOS!$C$9+G11*COSTOS!$C$10))) | N11: FACTURACIÓN | O11: =IFERROR(SUM(H5:H700),0)
L12: =IF(K12<>"",(IF(H12="","",H12-(C12*COSTOS!$C$6+D12*COSTOS!$C$7+E12*COSTOS!$C$8+F12*COSTOS!$C$9+G12*COSTOS!$C$10)))+K12,IF(H12="","",H12-(C12*COSTOS!$C$6+D12*COSTOS!$C$7+E12*COSTOS!$C$8+F12*COSTOS!$C$9+G12*COSTOS!$C$10))) | N12: GANANCIA | O12: =IFERROR(SUM(L5:L700),0)
L13: =IF(K13<>"",(IF(H13="","",H13-(C13*COSTOS!$C$6+D13*COSTOS!$C$7+E13*COSTOS!$C$8+F13*COSTOS!$C$9+G13*COSTOS!$C$10)))+K13,IF(H13="","",H13-(C13*COSTOS!$C$6+D13*COSTOS!$C$7+E13*COSTOS!$C$8+F13*COSTOS!$C$9+G13*COSTOS!$C$10))) | N13: % GANANCIA | O13: =IFERROR(SUM(L5:L700)/SUM(H5:H700),0)
L14: =IF(K14<>"",(IF(H14="","",H14-(C14*COSTOS!$C$6+D14*COSTOS!$C$7+E14*COSTOS!$C$8+F14*COSTOS!$C$9+G14*COSTOS!$C$10)))+K14,IF(H14="","",H14-(C14*COSTOS!$C$6+D14*COSTOS!$C$7+E14*COSTOS!$C$8+F14*COSTOS!$C$9+G14*COSTOS!$C$10)))
L15: =IF(K15<>"",(IF(H15="","",H15-(C15*COSTOS!$C$6+D15*COSTOS!$C$7+E15*COSTOS!$C$8+F15*COSTOS!$C$9+G15*COSTOS!$C$10)))+K15,IF(H15="","",H15-(C15*COSTOS!$C$6+D15*COSTOS!$C$7+E15*COSTOS!$C$8+F15*COSTOS!$C$9+G15*COSTOS!$C$10))) | N15: EFECTIVO | O15: =IFERROR(SUM(I5:I700),0)
L16: =IF(K16<>"",(IF(H16="","",H16-(C16*COSTOS!$C$6+D16*COSTOS!$C$7+E16*COSTOS!$C$8+F16*COSTOS!$C$9+G16*COSTOS!$C$10)))+K16,IF(H16="","",H16-(C16*COSTOS!$C$6+D16*COSTOS!$C$7+E16*COSTOS!$C$8+F16*COSTOS!$C$9+G16*COSTOS!$C$10))) | N16: TRANSFERENCIA | O16: =IFERROR(SUM(J5:J700),0)
L17: =IF(K17<>"",(IF(H17="","",H17-(C17*COSTOS!$C$6+D17*COSTOS!$C$7+E17*COSTOS!$C$8+F17*COSTOS!$C$9+G17*COSTOS!$C$10)))+K17,IF(H17="","",H17-(C17*COSTOS!$C$6+D17*COSTOS!$C$7+E17*COSTOS!$C$8+F17*COSTOS!$C$9+G17*COSTOS!$C$10)))
L18: =IF(K18<>"",(IF(H18="","",H18-(C18*COSTOS!$C$6+D18*COSTOS!$C$7+E18*COSTOS!$C$8+F18*COSTOS!$C$9+G18*COSTOS!$C$10)))+K18,IF(H18="","",H18-(C18*COSTOS!$C$6+D18*COSTOS!$C$7+E18*COSTOS!$C$8+F18*COSTOS!$C$9+G18*COSTOS!$C$10))) | N18: Nº VENTAS | O18: =IFERROR(COUNTA(B5:B700),0)
L19: =IF(K19<>"",(IF(H19="","",H19-(C19*COSTOS!$C$6+D19*COSTOS!$C$7+E19*COSTOS!$C$8+F19*COSTOS!$C$9+G19*COSTOS!$C$10)))+K19,IF(H19="","",H19-(C19*COSTOS!$C$6+D19*COSTOS!$C$7+E19*COSTOS!$C$8+F19*COSTOS!$C$9+G19*COSTOS!$C$10))) | N19: DÍAS DEL MES | O19: 31
L20: =IF(K20<>"",(IF(H20="","",H20-(C20*COSTOS!$C$6+D20*COSTOS!$C$7+E20*COSTOS!$C$8+F20*COSTOS!$C$9+G20*COSTOS!$C$10)))+K20,IF(H20="","",H20-(C20*COSTOS!$C$6+D20*COSTOS!$C$7+E20*COSTOS!$C$8+F20*COSTOS!$C$9+G20*COSTOS!$C$10)))
L21: =IF(K21<>"",(IF(H21="","",H21-(C21*COSTOS!$C$6+D21*COSTOS!$C$7+E21*COSTOS!$C$8+F21*COSTOS!$C$9+G21*COSTOS!$C$10)))+K21,IF(H21="","",H21-(C21*COSTOS!$C$6+D21*COSTOS!$C$7+E21*COSTOS!$C$8+F21*COSTOS!$C$9+G21*COSTOS!$C$10))) | N21: OBJETIVO ($)
